Workbook

Sheet Summary
A1: GEARBOX LEADS - MASTER FILE, ALL 7 MARKETS
A2: 1,400 contacts | 1017 companies | 7 markets | zero duplicate people across markets
A3: Source: Apollo.io, batches pulled Aug 2026 | Filter the Leads tab by Market (column H) to work one market at a time
A5: BY MARKET
A6: Market | B6: Batch | C6: Contacts | D6: Companies | E6: Language / note
A7: Southern Africa | B7: 1 | C7: =COUNTIF(Leads!$H$2:$H$1401,A7) | D7: 134 | E7: English; ZA/Zambia/Botswana etc - mining & sugar heavy
A8: Lithuania | B8: 2 | C8: =COUNTIF(Leads!$H$2:$H$1401,A8) | D8: 145 | E8: English; EU, truck 10-15 days
A9: Cote d'Ivoire | B9: 3 | C9: =COUNTIF(Leads!$H$2:$H$1401,A9) | D9: 144 | E9: FRENCH mails; cocoa, mining, ports
A10: Turkey | B10: 4 | C10: =COUNTIF(Leads!$H$2:$H$1401,A10) | D10: 182 | E10: Turkish; home market
A11: Latvia | B11: 5 | C11: =COUNTIF(Leads!$H$2:$H$1401,A11) | D11: 137 | E11: English; EU, wood & machine builders
A12: Estonia | B12: 6 | C12: =COUNTIF(Leads!$H$2:$H$1401,A12) | D12: 144 | E12: English; EU, wood & machine builders
A13: Nigeria | B13: 7 | C13: =COUNTIF(Leads!$H$2:$H$1401,A13) | D13: 131 | E13: English; phone-first market, 80 direct numbers in file
A14: TOTAL | C14: =SUM(C7:C13) | D14: 1017
A16: BY SEGMENT
A17: Segment | B17: Contacts | C17: Companies
A18: Distributor | B18: =COUNTIF(Leads!$I$2:$I$1401,A18) | C18: 180
A19: Machine Builder | B19: =COUNTIF(Leads!$I$2:$I$1401,A19) | C19: 153
A20: Food & Agro | B20: =COUNTIF(Leads!$I$2:$I$1401,A20) | C20: 111
A21: Materials/Construction | B21: =COUNTIF(Leads!$I$2:$I$1401,A21) | C21: 73
A22: Materials/Packaging | B22: =COUNTIF(Leads!$I$2:$I$1401,A22) | C22: 78
A23: Wood/Timber | B23: =COUNTIF(Leads!$I$2:$I$1401,A23) | C23: 62
A24: Port/Energy | B24: =COUNTIF(Leads!$I$2:$I$1401,A24) | C24: 63
A25: Mining | B25: =COUNTIF(Leads!$I$2:$I$1401,A25) | C25: 14
A26: Agro-Processing | B26: =COUNTIF(Leads!$I$2:$I$1401,A26) | C26: 20
A27: Agro/Cement | B27: =COUNTIF(Leads!$I$2:$I$1401,A27) | C27: 28
A28: Wood/Packaging | B28: =COUNTIF(Leads!$I$2:$I$1401,A28) | C28: 27
A29: Steel & Metals | B29: =COUNTIF(Leads!$I$2:$I$1401,A29) | C29: 25
... A40: Agro/Food | B40: =COUNTIF(Leads!$I$2:$I$1401,A40) | C40: 6
A42: TRACKING (whole file)
A43: Status | B43: Count
A44: Emailed | B44: =COUNTIF(Leads!$U$2:$U$1401,A44)
A45: Replied | B45: =COUNTIF(Leads!$U$2:$U$1401,A45)
A46: Meeting | B46: =COUNTIF(Leads!$U$2:$U$1401,A46)
A47: Quoted | B47: =COUNTIF(Leads!$U$2:$U$1401,A47)
A48: Won | B48: =COUNTIF(Leads!$U$2:$U$1401,A48)
A49: Not interested | B49: =COUNTIF(Leads!$U$2:$U$1401,A49)
A51: HOW TO WORK THE MASTER FILE
A52: 1. This file merges your 7 market lists into one place. The single-market files still exist - pick ONE home for tracking (this file or the country files), do not tick both.
A53: 2. Work market by market: filter Leads by Market (column H). Language differs - Cote d'Ivoire is FRENCH, Turkey is TURKISH, the rest English. The Language column is per person.
A54: 3. Sending pace still applies PER DAY overall, not per market: max 20-30 emails/day from your Outlook, colleagues in BCC not CC. This file is roughly 3 months of steady sending.
...

Sheet Leads
A1: First name | B1: Last name | C1: Email address | D1: Company | E1: Title | F1: Country | G1: City | H1: Market | I1: Segment | J1: Tier | K1: Language | L1: LinkedIn | M1: Company domain | N1: Company phone | O1: Direct/Mobile phone | P1: Employees | Q1: Industry | R1: Suggested angle | S1: Salutation | T1: Name check | U1: Status | V1: Date sent | W1: Replied | X1: Notes
A2: Ivo | B2: Araujo | C2: ivo.araujo@centrocar.com | D2: CENTROCAR - Centro de Equipamentos Mecânicos S.A. | E2: General Manager Angola | F2: Angola | G2: Luanda | H2: Southern Africa | I2: Distributor | J2: A | K2: Portuguese | L2: http://www.linkedin.com/in/ivo-araujo-9470b849 | M2: centrocar.com | N2: +351 22 002 9150 | P2: 150 | Q2: machinery | R2: Stocking terms and margin - lead with the commercial offer to the MD/GM, not the spec sheet | S2: Sr.
A3: Luca | B3: Sassella | C3: luca.sassella@eats.ao | D3: E.A.T.S Metering Systems | E3: Managing Director | F3: Angola | H3: Southern Africa | I3: Distributor | J3: A | K3: Portuguese | L3: http://www.linkedin.com/in/luca-sassella-6b69765 | M3: eats.ao | N3: +244 931 878 469 | P3: 9 | Q3: oil & energy | R3: Stocking terms and margin - lead with the commercial offer to the MD/GM, not the spec sheet | S3: Sr.
A4: Eduardo | B4: Fernandez | C4: eduardo.fernandez@encom.it.ao | D4: ENCOM Lda. | E4: Managing Director | F4: Angola | G4: Luanda | H4: Southern Africa | I4: Distributor | J4: A | K4: Portuguese | L4: http://www.linkedin.com/in/edufernandez | M4: encom.it.ao | N4: +1 713-429-5084 | P4: 24 | Q4: oil & energy | R4: Stocking terms and margin - lead with the commercial offer to the MD/GM, not the spec sheet | S4: Sr.
A5: Jose | B5: Santos | C5: josesantos@enerline.ao | D5: ENERLINE, SA | E5: General Manager | F5: Angola | G5: Luanda | H5: Southern Africa | I5: Distributor | J5: A | K5: Portuguese | L5: http://www.linkedin.com/in/jose-santos-9193b9253 | M5: enerline.ao | P5: 250 | Q5: oil & energy | R5: Stocking terms and margin - lead with the commercial offer to the MD/GM, not the spec sheet | S5: Sr.
A6: Jose | B6: Garrido | C6: jlgarrido@elecnor.com | D6: Elecnor Group | E6: Director Geral Adjunto de Sucursal Angola | F6: Angola | G6: Luanda | H6: Southern Africa | I6: Distributor | J6: A | K6: Portuguese | L6: http://www.linkedin.com/in/jose-luis-garrido-34110623 | M6: grupoelecnor.com | P6: 29000 | Q6: construction | R6: Stocking terms and margin - lead with the commercial offer to the MD/GM, not the spec sheet | S6: Sr.
A7: Januario | B7: Cuela | C7: januario.cuela@gea.com | D7: GEA Group | E7: Branch Manager Angola | F7: Angola | H7: Southern Africa | I7: Distributor | J7: A | K7: Portuguese | L7: http://www.linkedin.com/in/januario-cuela-985a1538 | M7: gea.com | N7: +49 211 91360 | P7: 20000 | Q7: machinery | R7: Stocking terms and margin - lead with the commercial offer to the MD/GM, not the spec sheet | S7: Sr.
A8: Rayan | B8: Farhat | C8: rayan.farhat@industryhubangola.com | D8: Industryhub | E8: Managing Director and Founder | F8: Angola | G8: Luanda | H8: Southern Africa | I8: Distributor | J8: A | K8: Portuguese | L8: http://www.linkedin.com/in/rayan-farhat | M8: industryhubangola.com | P8: 11 | Q8: automotive | R8: Stocking terms and margin - lead with the commercial offer to the MD/GM, not the spec sheet | S8: Sr.
A9: Nasim | B9: Kayali | C9: n.kayali@mecanixsal.com | D9: Mega Mecanix | E9: General Manager | F9: Angola | H9: Southern Africa | I9: Distributor | J9: A | K9: Portuguese | L9: http://www.linkedin.com/in/nasim-kayali-0bbb2937 | M9: mecanixsal.com | N9: +961 5 950 866 | P9: 19 | Q9: machinery | R9: Stocking terms and margin - lead with the commercial offer to the MD/GM, not the spec sheet | S9: Sr.
A10: Paulo | B10: Rodrigues | C10: paulo.rodrigues@movicortes.pt | D10: Movicortes Angola | E10: General Manager | F10: Angola | G10: Luanda | H10: Southern Africa | I10: Distributor | J10: A | K10: Portuguese | L10: http://www.linkedin.com/in/paulo-rodrigues-a35823164 | M10: movicortesangola.com | P10: 7 | Q10: machinery | R10: Stocking terms and margin - lead with the commercial offer to the MD/GM, not the spec sheet | S10: Sr.
A11: Peter | B11: Mashangu | C11: peter.mashangu@nampak.com | D11: Nampak | E11: Managing Director | F11: Angola | G11: Luanda | H11: Southern Africa | I11: Distributor | J11: A | K11: Portuguese | L11: http://www.linkedin.com/in/peter-mashangu-394611159 | M11: nampak.com | N11: +27 11 719 6300 | P11: 2500 | Q11: packaging & containers | R11: Stocking terms and margin - lead with the commercial offer to the MD/GM, not the spec sheet | S11: Sr.
A12: Kitana | B12: Barbosa | C12: kbarbosa@nors.com | D12: Nors Group | E12: After Sales Director | F12: Angola | G12: Luanda | H12: Southern Africa | I12: Distributor | J12: A | K12: Portuguese | L12: http://www.linkedin.com/in/kitana-barbosa-b3b58486 | M12: nors.com | N12: +351 22 615 0320 | P12: 3200 | Q12: automotive | R12: Stocking terms and margin - lead with the commercial offer to the MD/GM, not the spec sheet | S12: Sr.ª | T12: Set to Ms. - confirm
A13: Jean | B13: Rodrigues | C13: jean-philippe.rodrigues@og3s-mecanica.com | D13: OG3S Mecanica Lda | E13: Executive Managing Director | F13: Angola | H13: Southern Africa | I13: Distributor | J13: A | K13: Portuguese | L13: http://www.linkedin.com/in/jean-philippe-rodrigues-a727b82b | M13: og3s-mecanica.com | P13: 35 | Q13: oil & energy | R13: Stocking terms and margin - lead with the commercial offer to the MD/GM, not the spec sheet | S13: Sr.
A14: Luis | B14: Almeida | C14: l.almeida@spie.com | D14: SPIE Global Services Energy | E14: Managing Director Angola & Mozambique | F14: Angola | G14: Luanda | H14: Southern Africa | I14: Distributor | J14: A | K14: Portuguese | L14: http://www.linkedin.com/in/luis-ferreira-de-almeida-34495338 | M14: spie.com | N14: +33 1 34 41 81 81 | P14: 5000 | Q14: oil & energy | R14: Stocking terms and margin - lead with the commercial offer to the MD/GM, not the spec sheet | S14: Sr.
A15: Nicolas | B15: Monville | C15: nicolas.monville@grouptfe.com | D15: TFE GROUP INC | E15: Managing Director | F15: Angola | H15: Southern Africa | I15: Distributor | J15: A | K15: Portuguese | L15: http://www.linkedin.com/in/nicolas-monville-411a6358 | M15: grouptfe.com | N15: +33 4 66 70 64 10 | P15: 45 | Q15: oil & energy | R15: Stocking terms and margin - lead with the commercial offer to the MD/GM, not the spec sheet | S15: Sr.
A16: Mathieu | B16: Wallach | C16: mwallach@welltec.com | D16: Welltec | E16: Sales Director and General Manager, Southern Africa | F16: Angola | H16: Southern Africa | I16: Distributor | J16: A | K16: Portuguese | L16: http://www.linkedin.com/in/mathieu-wallach-a9203a59 | M16: welltec.com | N16: +45 48 14 35 14 | P16: 740 | Q16: oil & energy | R16: Stocking terms and margin - lead with the commercial offer to the MD/GM, not the spec sheet | S16: Sr.
A17: Favor | B17: Marebole | C17: favor@appliedmetrology.co.za | D17: Applied Metrology Services (Pty) Ltd. | E17: Managing Director | F17: Botswana | H17: Southern Africa | I17: Distributor | J17: A | K17: English | L17: http://www.linkedin.com/in/favor-marebole-a060559 | M17: appliedmetrology.co.za | N17: +27 11 568 0386 | P17: 12 | Q17: machinery | R17: Stocking terms and margin - lead with the commercial offer to the MD/GM, not the spec sheet | S17: Mr. | T17: Unisex name - confirm Mr./Ms.
A18: Bofedile | B18: Moeti | C18: bmoeti@bts-bw.com | D18: Bofedile Tech Services (Pty) Ltd | E18: Managing Director | F18: Botswana | G18: Gaborone | H18: Southern Africa | I18: Distributor | J18: A | K18: English | L18: http://www.linkedin.com/in/bofedile-moeti-6b1b0447 | M18: bts-bw.com | P18: 6 | Q18: industrial automation | R18: Stocking terms and margin - lead with the commercial offer to the MD/GM, not the spec sheet | S18: Mr. | T18: Unisex name - confirm Mr./Ms.
A19: Wessel | B19: Wessels | C19: wessel@coastalhire.co.za | D19: Coastal Hire | E19: Managing Director | F19: Botswana | H19: Southern Africa | I19: Distributor | J19: A | K19: English | L19: http://www.linkedin.com/in/wessel-wessels-086569146 | M19: coastalhire.co.za | N19: +27 10 158 0525 | P19: 260 | Q19: construction / equipment hire | R19: Stocking terms and margin - lead with the commercial offer to the MD/GM, not the spec sheet | S19: Mr.
A20: Tichaona | B20: Ndhlovu | C20: tndhlovu@delswizgroup.com | D20: Delswiz Manufacturing (Pty) Limited | E20: Managing Director | F20: Botswana | G20: Gaborone | H20: Southern Africa | I20: Distributor | J20: A | K20: English | L20: http://www.linkedin.com/in/tichaona-ndhlovu-93212b141 | M20: delswizgroup.com | N20: +971 55 157 9261 | P20: 26 | Q20: mining & metals | R20: Stocking terms and margin - lead with the commercial offer to the MD/GM, not the spec sheet | S20: Mr.
A21: Clayton | B21: Davis | C21: clayton.davis@hansa-flex.com | D21: HANSA-FLEX AG | E21: General Manager | F21: Botswana | H21: Southern Africa | I21: Distributor | J21: A | K21: English | L21: http://www.linkedin.com/in/clayton-davis-a18a377b | M21: hansa-flex.de | N21: +49 42 1489070 | P21: 5200 | Q21: machinery / hydraulics | R21: Stocking terms and margin - lead with the commercial offer to the MD/GM, not the spec sheet | S21: Mr.
A22: Zayd | B22: Bhoyroo | C22: zayd@impex.co.bw | D22: Impex Group | E22: Assistant General Manager | F22: Botswana | H22: Southern Africa | I22: Distributor | J22: A | K22: English | L22: http://www.linkedin.com/in/zayd-bhoyroo-41419b161 | M22: impex.co.bw | P22: 26 | Q22: automotive / wholesale | R22: Stocking terms and margin - lead with the commercial offer to the MD/GM, not the spec sheet | S22: Mr.
A23: Sonny | B23: Morekisi | C23: sonnym@komatsu.co.za | D23: Komatsu Africa Holdings (Pty) Ltd | E23: Branch Manager | F23: Botswana | H23: Southern Africa | I23: Distributor | J23: A | K23: English | L23: http://www.linkedin.com/in/sonny-morekisi-9b921043 | M23: komatsu.co.za | P23: 360 | Q23: machinery | R23: Stocking terms and margin - lead with the commercial offer to the MD/GM, not the spec sheet | S23: Mr.
A24: Donovan | B24: Lendrum | C24: donovan@rotatingsolutions.co.bw | D24: Rotating Solutions Botswana | E24: Sales Director | F24: Botswana | G24: Gaborone | H24: Southern Africa | I24: Distributor | J24: A | K24: English | L24: http://www.linkedin.com/in/donovan-lendrum-906a6352 | M24: rotatingsolutions.co.bw | P24: 2 | Q24: industrial supply / bearings and lubricants | R24: Stocking terms and margin - lead with the commercial offer to the MD/GM, not the spec sheet | S24: Mr.
A25: Tshegofatso | B25: Mosweu | C25: tshegofatso@sptc.com.sa | D25: SPTC | E25: Assistant Manager Procurement | F25: Botswana | H25: Southern Africa | I25: Distributor | J25: A | K25: English | L25: http://www.linkedin.com/in/tshegofatso-mosweu-783017a1 | M25: sptc.com.sa | N25: +966 13 814 4624 | P25: 320 | Q25: electrical/electronic manufacturing | R25: Stocking terms and margin - lead with the commercial offer to the MD/GM, not the spec sheet | S25: Mr. | T25: Unisex name - confirm Mr./Ms.
A26: Justice | B26: Moilwa | C26: jmoilwa@zismoengineering.com | D26: ZISMO Engineering (Pty) Ltd. | E26: Managing Director | F26: Botswana | G26: Gaborone | H26: Southern Africa | I26: Distributor | J26: A | K26: English | L26: http://www.linkedin.com/in/justice-moilwa-859595ba | M26: zismoengineeing.com | N26: +267 393 2711 | P26: 58 | Q26: electrical/electronic manufacturing | R26: Stocking terms and margin - lead with the commercial offer to the MD/GM, not the spec sheet | S26: Mr.
A27: Michael | B27: Bentley | C27: m.bentley@actionautozambia.com | D27: ACTION AUTO ZAMBIA | E27: Managing Director | F27: Zambia | H27: Southern Africa | I27: Distributor | J27: A | K27: English | L27: http://www.linkedin.com/in/michael-bentley-69240073 | M27: actionautozambia.com | P27: 54 | Q27: automotive | R27: Stocking terms and margin - lead with the commercial offer to the MD/GM, not the spec sheet | S27: Mr. | X27: Sent 29-Jul-2026 07:53 from Outlook, cc Haffar, Kayacan, Nesren. Delivered, no bounce.
A28: Sajad | B28: Ahmed | C28: sajad@accessenergys.com | D28: Access Energy Solutions Pty Ltd | E28: MD | F28: Zambia | H28: Southern Africa | I28: Distributor | J28: A | K28: English | L28: http://www.linkedin.com/in/sajad-ahmed-2ba5b5112 | M28: accessenergys.com | P28: 4 | Q28: environmental services | R28: Stocking terms and margin - lead with the commercial offer to the MD/GM, not the spec sheet | S28: Mr. | X28: Sent 29-Jul-2026 07:56 from Outlook, cc Haffar, Kayacan, Nesren, Tahir. Delivered, no bounce.
A29: Dirk | B29: Wet | C29: dirk.dewet@biagroup.com | D29: BIA GROUP | E29: Project Operation Manager | F29: Zambia | G29: Lusaka | H29: Southern Africa | I29: Distributor | J29: A | K29: English | L29: http://www.linkedin.com/in/dirk-de-wet-8969b189 | M29: biagroup.com | N29: +32 2 689 28 11 | P29: 1300 | Q29: machinery | R29: Stocking terms and margin - lead with the commercial offer to the MD/GM, not the spec sheet | S29: Mr.
A30: Cobus | B30: Potgieter | C30: cobus@bldequipment.com | D30: BL&D Plant Hire & Sales | E30: Branch Manager | F30: Zambia | H30: Southern Africa | I30: Distributor | J30: A | K30: English | L30: http://www.linkedin.com/in/cobus-potgieter-68204494 | M30: bldequipment.com | P30: 76 | Q30: machinery | R30: Stocking terms and margin - lead with the commercial offer to the MD/GM, not the spec sheet | S30: Mr.
A31: Samson | B31: Chingozho | C31: samson.chingozho@bellequipment.com | D31: Bell Equipment Mining & Construction | E31: Managing Director | F31: Zambia | H31: Southern Africa | I31: Distributor | J31: A | K31: English | L31: http://www.linkedin.com/in/samson-chingozho-b584a212 | M31: bellequipment.com | N31: +27 35 907 9111 | P31: 3500 | Q31: machinery | R31: Stocking terms and margin - lead with the commercial offer to the MD/GM, not the spec sheet | S31: Mr.
A32: Bevin | B32: Samwata | C32: bevin.samwata@blumaq.com | D32: Blumaq, S.A. | E32: Branch Manager | F32: Zambia | G32: Kitwe | H32: Southern Africa | I32: Distributor | J32: A | K32: English | L32: http://www.linkedin.com/in/bevin-samwata-76765a64 | M32: blumaq.com | N32: +34 964 69 70 30 | P32: 250 | Q32: machinery | R32: Stocking terms and margin - lead with the commercial offer to the MD/GM, not the spec sheet | S32: Mr.
A33: Henry | B33: Kapesa | C33: henry@bordertecltd.com | D33: Bordertec Limited | E33: Managing Director | F33: Zambia | H33: Southern Africa | I33: Distributor | J33: A | K33: English | L33: http://www.linkedin.com/in/henry-kapesa-044b16aa | M33: bordertec.co.zm | P33: 5 | Q33: management consulting | R33: Stocking terms and margin - lead with the commercial offer to the MD/GM, not the spec sheet | S33: Mr.
A34: Jinu | B34: Raj | C34: jinu@dgc-africa.com | D34: DGC AFRICA | E34: General Manager | F34: Zambia | H34: Southern Africa | I34: Distributor | J34: A | K34: English | L34: http://www.linkedin.com/in/jinu-raj-b51a2b15a | M34: dgc-africa.com | N34: +27 16 421 3720 | P34: 200 | Q34: mining & metals | R34: Stocking terms and margin - lead with the commercial offer to the MD/GM, not the spec sheet | S34: Mr.
A35: Gregory | B35: Gavazzi | C35: greg@doppioequipment.com | D35: Doppio Mining Equipment | E35: Managing Director | F35: Zambia | H35: Southern Africa | I35: Distributor | J35: A | K35: English | L35: http://www.linkedin.com/in/gregory-gavazzi-97ba9713a | M35: doppioequipment.com | P35: 4 | Q35: mining & metals | R35: Stocking terms and margin - lead with the commercial offer to the MD/GM, not the spec sheet | S35: Mr.
A36: Chongo | B36: Mumba | C36: chongom@aoj-pump.com | D36: Hebei Aojin Machinery Co.,Ltd. | E36: Technical Sales Manager | F36: Zambia | H36: Southern Africa | I36: Distributor | J36: A | K36: English | L36: http://www.linkedin.com/in/chongo-mumba-13295520 | M36: aoj-pump.com | N36: +86 311 8880 2472 | P36: 150 | Q36: machinery | R36: Stocking terms and margin - lead with the commercial offer to the MD/GM, not the spec sheet | S36: Mr.
A37: Arne | B37: Thorkildsen | C37: arne.thorkildsen@hcmaf.com | D37: Hitachi Construction Machinery | E37: Branch Operations Manager | F37: Zambia | H37: Southern Africa | I37: Distributor | J37: A | K37: English | L37: http://www.linkedin.com/in/arne-thorkildsen-336b2b82 | M37: hitachicm.com | N37: +81 358-26-8100 | P37: 26000 | Q37: machinery | R37: Stocking terms and margin - lead with the commercial offer to the MD/GM, not the spec sheet | S37: Mr.
A38: Henri | B38: Wassink | C38: hendrik.wassink@liebherr.com | D38: Liebherr Group | E38: Managing Director - Administration | F38: Zambia | H38: Southern Africa | I38: Distributor | J38: A | K38: English | L38: http://www.linkedin.com/in/henri-wassink-60322140 | M38: liebherr.com | N38: +49 735 1410 | P38: 54000 | Q38: machinery | R38: Stocking terms and margin - lead with the commercial offer to the MD/GM, not the spec sheet | S38: Mr.
A39: Yoginder | B39: Singh | C39: yoginder@racsafrica.com | D39: R A Consulting Services (RACS) | E39: Workshop Manager | F39: Zambia | H39: Southern Africa | I39: Distributor | J39: A | K39: English | L39: http://www.linkedin.com/in/yoginder-singh-944003180 | M39: racsafrica.com | N39: +267 393 9773 | P39: 87 | Q39: information technology & services | R39: Stocking terms and margin - lead with the commercial offer to the MD/GM, not the spec sheet | S39: Mr.
A40: Simon | B40: Kazunda | C40: simon.kazunda@safekahya.com | D40: SAFE KAHYA Limited | E40: Managing Director | F40: Zambia | H40: Southern Africa | I40: Distributor | J40: A | K40: English | L40: http://www.linkedin.com/in/simon-kazunda-46655b21 | M40: safekahya.com | P40: 1 | Q40: electrical/electronic manufacturing | R40: Stocking terms and margin - lead with the commercial offer to the MD/GM, not the spec sheet | S40: Mr.
...

Sheet Read me
A1: HOW TO USE THIS FILE
A3: MASTER FILE - all 7 of your market lists in one workbook: Southern Africa, Lithuania, Cote d'Ivoire, Turkey, Latvia, Estonia, Nigeria. 1,400 people, no duplicates across markets.
A5: The single-market files still exist in the repo. IMPORTANT: pick one place to track progress - either this master file or the per-country files - and stick to it, otherwise your Status columns will disagree.
A7: LEADS tab - filter by Market (column H) to work one market at a time. Every row keeps its original Tier, Suggested angle, Salutation and Notes from the country file.
A8: LANGUAGE: Cote d'Ivoire rows are FRENCH, Turkey rows TURKISH, everything else English. Check the Language column before writing.
A9: DIRECT/MOBILE PHONE: filled for 80 Nigeria contacts (Apollo phone reveals). Other markets show only the company switchboard - say the word if you want phone reveals for them too.
A10: NAME CHECK (orange): unisex names (mainly Cote d'Ivoire and Nigeria) - glance at the LinkedIn photo before writing Mr./Ms.
A12: TIER A = distributors, machine builders, cement/mining. TIER B = plants (spares business).
A14: Track in the yellow columns (Status / Date sent / Replied / Notes). Summary counts recalculate when Excel opens the file.
A16: Reminders that apply everywhere:
A17: - Max 20-30 emails per day total from your Outlook, colleagues in BCC not CC.
A18: - A handful of emails are marked 'extrapolated' in Notes - not verified, use with care.
... A20: - Payment risk in Nigeria and West Africa: confirmed LC or advance for first orders, never open account.
