Workbook

Sheet Summary
A1: Gearbox Leads - Batch 1
A2: Botswana | Zambia | Angola - every contact has a verified email and a ready-to-send message
A4: By country
A5: Country | B5: Contacts
A6: Botswana | B6: =COUNTIF(Leads!$H$2:$H$201,A6)
A7: Zambia | B7: =COUNTIF(Leads!$H$2:$H$201,A7)
A8: Angola | B8: =COUNTIF(Leads!$H$2:$H$201,A8)
A9: Total | B9: =SUM(B6:B8)
A11: By segment
A12: Segment | B12: Contacts
A13: Distributor | B13: =COUNTIF(Leads!$J$2:$J$201,A13)
A14: Mining | B14: =COUNTIF(Leads!$J$2:$J$201,A14)
A15: Mining/Construction | B15: =COUNTIF(Leads!$J$2:$J$201,A15)
A16: Agro/Cement | B16: =COUNTIF(Leads!$J$2:$J$201,A16)
A17: Agro/Food | B17: =COUNTIF(Leads!$J$2:$J$201,A17)
A18: Energy/Oil&Gas | B18: =COUNTIF(Leads!$J$2:$J$201,A18)
A19: Energy/Logistics | B19: =COUNTIF(Leads!$J$2:$J$201,A19)
A20: Total | B20: =SUM(B13:B19)
A22: By priority tier - work A first
A23: Tier | B23: What it is | C23: Contacts
A24: A | B24: Distributors and dealers - resell, stock, buy repeatedly | C24: =COUNTIF(Leads!$K$2:$K$201,A24)
A25: B | B25: Mining - highest spend, downtime costs them per hour | C25: =COUNTIF(Leads!$K$2:$K$201,A25)
A26: C | B26: Other end users - agro, cement, energy, logistics | C26: =COUNTIF(Leads!$K$2:$K$201,A26)
A27: Total | C27: =SUM(C24:C26)
A29: Send language
A30: Language | B30: Contacts
A31: English | B31: =COUNTIF(Leads!$M$2:$M$201,A31)
A32: Portuguese | B32: =COUNTIF(Leads!$M$2:$M$201,A32)
A33: Angola is Portuguese. Those emails are already written in Portuguese.
A35: Outreach progress - fills in as you update the Status column
A36: Status | B36: Contacts
A37: Not contacted | B37: =COUNTIF(Leads!$U$2:$U$201,A37)
A38: Emailed | B38: =COUNTIF(Leads!$U$2:$U$201,A38)
A39: Follow-up sent | B39: =COUNTIF(Leads!$U$2:$U$201,A39)
A40: Replied | B40: =COUNTIF(Leads!$U$2:$U$201,A40)
A41: Meeting booked | B41: =COUNTIF(Leads!$U$2:$U$201,A41)
A42: Quoted | B42: =COUNTIF(Leads!$U$2:$U$201,A42)
A43: Not interested | B43: =COUNTIF(Leads!$U$2:$U$201,A43)
A44: Bounced | B44: =COUNTIF(Leads!$U$2:$U$201,A44)
A45: Reply rate | B45: =IFERROR(COUNTIF(Leads!$U$2:$U$201,"Replied")/MAX(1,COUNTIF(Leads!$U$2:$U$201,"Emailed")+COUNTIF(Leads!$U$2:$U$201,"Follow-up sent")+COUNTIF(Leads!$U$2:$U$201,"Replied")),0)
...

Sheet Mails
A1: One email per company
A2: 136 companies, 200 contacts. Each email names that company's own equipment.
A3: The whole email sits in ONE cell in the green column C - click it, copy, paste into your mail client. Ready as written; add your signature. The Leads tab has a copy addressed to each individual person.
A5: Code | B5: Company | C5: EMAIL - copy this cell | D5: Subject | E5: Send to | F5: Country | G5: Lang | H5: No. | I5: All contacts at this company
A6: C001 | B6: 260 Brands | C6: Hi Rahul, Plants like 260 Brands buy drive spares before the season, not during it - the mixer, conveyor and packing line drives on the plant cost far more to fix mid-run than to hold on the shelf. We supply helical, bevel-helical, planetary and shaft-mounted gearboxes - 10 to 14 days into Zambia for stocked sizes, with rebuild-on-exchange. If you tell me roughly when your next shutdown falls, I'll quote the units worth having in stock before it. | D6: Gearbox spares before your next shutdown - 260 Brands | E6: Rahul Singh <rahul.s@260brands.com> | F6: Zambia | G6: English | H6: =COUNTIF(Leads!$L$2:$L$201,A6) | I6: Rahul Singh (Production Manager)
A7: C002 | B7: ACTION AUTO ZAMBIA | C7: Hi Michael, ACTION AUTO ZAMBIA keeps its customers running, and the drivetrain and PTO gearboxes on the vehicles you support are what sit idle when a gearbox is on backorder. We supply industrial and mobile gearboxes - helical, bevel-helical, planetary, travel and swing drives - at trade pricing, 10 to 14 days into Zambia for stocked sizes. Most distributors we work with hold a small consignment of the units they move most, so a breakdown becomes a same-week fix instead of a six-week import. Can I send our range and dealer pricing? | D7: Gearbox supply for ACTION AUTO ZAMBIA | E7: Michael Bentley <m.bentley@actionautozambia.com> | F7: Zambia | G7: English | H7: =COUNTIF(Leads!$L$2:$L$201,A7) | I7: Michael Bentley (Managing Director)
A8: C003 | B8: AECI Mining | C8: Hi Seabi, At AECI Mining, the augers, mixers and conveyor drives on your emulsion plants are the units that stop production when a gearbox goes. The usual answer from suppliers is twelve weeks. We hold helical, bevel-helical and planetary gearboxes, and supply drop-in replacements for SEW-Eurodrive, Flender, Bonfiglioli and David Brown - 10 to 14 days into Botswana for stocked sizes, 4 to 6 weeks made to order, with rebuild-on-exchange. Send me the units on your critical spares list and I'll come back with price and lead time, so you have a second source on file before you need one. | D8: Gearbox lead times for AECI Mining | E8: Seabi Sekhobe <seabi.sekhobe@aeciworld.com> | F8: Botswana | G8: English | H8: =COUNTIF(Leads!$L$2:$L$201,A8) | I8: Seabi Sekhobe (Maintenance Manager)
A9: C004 | B9: Access Energy Solutions Pty Ltd | C9: Hi Sajad, Access Energy Solutions Pty Ltd keeps its customers running, and the gearboxes on the plant and energy equipment you supply are what sit idle when a gearbox is on backorder. We supply industrial and mobile gearboxes - helical, bevel-helical, planetary, travel and swing drives - at trade pricing, 10 to 14 days into Zambia for stocked sizes. Most distributors we work with hold a small consignment of the units they move most, so a breakdown becomes a same-week fix instead of a six-week import. Can I send our range and dealer pricing? | D9: Gearbox supply for Access Energy Solutions Pty Ltd | E9: Sajad Ahmed <sajad@accessenergys.com> | F9: Zambia | G9: English | H9: =COUNTIF(Leads!$L$2:$L$201,A9) | I9: Sajad Ahmed (MD)
A10: C005 | B10: Advanta Seeds | C10: Hi Innocent, Plants like Advanta Seeds buy drive spares before the season, not during it - the seed processing, grading and conveyor drives on the plant cost far more to fix mid-run than to hold on the shelf. We supply helical, bevel-helical, planetary and shaft-mounted gearboxes - 10 to 14 days into Zambia for stocked sizes, with rebuild-on-exchange. If you tell me roughly when your next shutdown falls, I'll quote the units worth having in stock before it. | D10: Gearbox spares before your next shutdown - Advanta Seeds | E10: Innocent Mwaanga <innocent.mwaanga@advantaseeds.com> | F10: Zambia | G10: English | H10: =COUNTIF(Leads!$L$2:$L$201,A10) | I10: Innocent Mwaanga (Production Manager)
A11: C006 | B11: Africa Global Logistics | C11: Hi Mwila, At Africa Global Logistics, the materials handling, crane and conveyor drives at the terminals fail the same way everywhere: the machine is available, the gearbox is not. We supply industrial, shaft-mounted and mobile gearboxes plus travel and swing drives - 10 to 14 days into Zambia for stocked sizes, with rebuild-on-exchange. Send me the drives that give you the most trouble and I'll come back with price and lead time. If we are not better than your current source, nothing lost. | D11: Drive and gearbox spares for Africa Global Logistics | E11: Mwila Chisanga <mwila.chisanga@aglgroup.com> | F11: Zambia | G11: English | H11: =COUNTIF(Leads!$L$2:$L$201,A11) | I11: Mwila Chisanga (Operations Manager IFFS)
A12: C007 | B12: African Mining Services | C12: Hi Tlamelo, At African Mining Services, the drivetrains and final drives across your contract fleet are the units that stop production when a gearbox goes. The usual answer from suppliers is twelve weeks. We hold helical, bevel-helical and planetary gearboxes, and supply drop-in replacements for SEW-Eurodrive, Flender, Bonfiglioli and David Brown - 10 to 14 days into Botswana for stocked sizes, 4 to 6 weeks made to order, with rebuild-on-exchange. Send me the units on your critical spares list and I'll come back with price and lead time, so you have a second source on file before you need one. | D12: Gearbox lead times for African Mining Services | E12: Tlamelo Rapata <trapata@amsgh.com> | F12: Botswana | G12: English | H12: =COUNTIF(Leads!$L$2:$L$201,A12) | I12: Tlamelo Rapata (Maintenance Manager)
A13: C008 | B13: Applied Metrology Services (Pty) Ltd. | C13: Hi Favor, Applied Metrology Services (Pty) Ltd. keeps its customers running, and the gearboxes on the process equipment you calibrate and service are what sit idle when a gearbox is on backorder. We supply industrial and mobile gearboxes - helical, bevel-helical, planetary, travel and swing drives - at trade pricing, 10 to 14 days into Botswana for stocked sizes. Most distributors we work with hold a small consignment of the units they move most, so a breakdown becomes a same-week fix instead of a six-week import. Can I send our range and dealer pricing? | D13: Gearbox supply for Applied Metrology Services (Pty) Ltd. | E13: Favor Marebole <favor@appliedmetrology.co.za> | F13: Botswana | G13: English | H13: =COUNTIF(Leads!$L$2:$L$201,A13) | I13: Favor Marebole (Managing Director)
A14: C009 | B14: Austin Powder | C14: Hi Brian, Plants like Austin Powder buy drive spares before the season, not during it - the mixers, augers and conveyor drives on your plant cost far more to fix mid-run than to hold on the shelf. We supply helical, bevel-helical, planetary and shaft-mounted gearboxes - 10 to 14 days into Zambia for stocked sizes, with rebuild-on-exchange. If you tell me roughly when your next shutdown falls, I'll quote the units worth having in stock before it. | D14: Gearbox spares before your next shutdown - Austin Powder | E14: Brian Mutale <brian.mutale@austinpowder.com> | F14: Zambia | G14: English | H14: =COUNTIF(Leads!$L$2:$L$201,A14) | I14: Brian Mutale (Plant Manager)
A15: C010 | B15: Azule Energy | C15: Olá Tatiana, Grande parte da despesa em redutores concentra-se num único fornecedor com prazos longos. Funciona até a unidade estar em rutura - e na Azule Energy isso significa os accionamentos dos guinchos, gruas e sistemas de amarração nas FPSO. Fornecemos redutores helicoidais, cónicos e planetários, e substituições compatíveis com SEW-Eurodrive, Flender, Bonfiglioli e David Brown - 10 a 14 dias até Angola para as medidas em stock, 4 a 6 semanas por encomenda, com recondicionamento por troca. Não é preciso mudar de fornecedor: basta consultarem-nos como segunda fonte. O que precisam da nossa parte para o registo de fornecedor? | D15: Segunda fonte para redutores - Azule Energy | E15: Tatiana Malheiro <tatiana.malheiro@azule-energy.com> | F15: Angola | G15: Portuguese | H15: =COUNTIF(Leads!$L$2:$L$201,A15) | I15: Tatiana Malheiro (Procurement Operations Manager), Xavier Riou (Engineering Manager), Davide Guttoriello (Contracts and Procurement Manager (Eni Secondee)), Nivaldo Vicente (Rigs & LLI’s Procurement), Cipriano Kakeu (Subsea Inspection, Maintenance & Repair and Vessel Manager)
A16: C011 | B16: BEFCO - Indústria | C16: Olá Malek, Fábricas como a BEFCO - Indústria compram peças de transmissão antes da campanha, não durante - os accionamentos dos misturadores, transportadores e linhas de produção custam muito mais a reparar em produção do que a ter em stock. Fornecemos redutores helicoidais, cónicos, planetários e de eixo oco - 10 a 14 dias até Angola para as medidas em stock, com recondicionamento por troca. Se me indicar a data da próxima paragem, orçamento as unidades que deveriam estar em stock antes disso. | D16: Redutores antes da próxima paragem - BEFCO - Indústria | E16: Malek Nazha <mnazha@befco-industria.com> | F16: Angola | G16: Portuguese | H16: =COUNTIF(Leads!$L$2:$L$201,A16) | I16: Malek Nazha (Plant Manager)
A17: C012 | B17: BIA GROUP | C17: Hi Dirk, BIA GROUP keeps its customers running, and the final drives, travel and swing drives on the machines you support are what sit idle when a gearbox is on backorder. We supply industrial and mobile gearboxes - helical, bevel-helical, planetary, travel and swing drives - at trade pricing, 10 to 14 days into Zambia for stocked sizes. Most distributors we work with hold a small consignment of the units they move most, so a breakdown becomes a same-week fix instead of a six-week import. Can I send our range and dealer pricing? | D17: Gearbox supply for BIA GROUP | E17: Dirk Wet <dirk.dewet@biagroup.com> | F17: Zambia | G17: English | H17: =COUNTIF(Leads!$L$2:$L$201,A17) | I17: Dirk Wet (Project Operation Manager), Johannes Subowo (Workshop Manager)
... A141: C136 | B141: ZISMO Engineering (Pty) Ltd. | C141: Hi Justice, ZISMO Engineering (Pty) Ltd. keeps its customers running, and the gearboxes that pair with the motors and drives you already rebuild are what sit idle when a gearbox is on backorder. We supply industrial and mobile gearboxes - helical, bevel-helical, planetary, travel and swing drives - at trade pricing, 10 to 14 days into Botswana for stocked sizes. Most distributors we work with hold a small consignment of the units they move most, so a breakdown becomes a same-week fix instead of a six-week import. Can I send our range and dealer pricing? | D141: Gearbox supply for ZISMO Engineering (Pty) Ltd. | E141: Justice Moilwa <jmoilwa@zismoengineering.com> | F141: Botswana | G141: English | H141: =COUNTIF(Leads!$L$2:$L$201,A141) | I141: Justice Moilwa (Managing Director)

Sheet Leads
A1: First name | B1: Last name | C1: Company | D1: EMAIL - copy this cell | E1: Subject | F1: Email address | G1: Title | H1: Country | I1: City | J1: Segment | K1: Tier | L1: Co. code | M1: Language | N1: LinkedIn | O1: Company domain | P1: Company phone | Q1: Employees | R1: Industry | S1: Suggested angle | T1: Check | U1: Status | V1: Date sent | W1: Replied | X1: Notes
A2: Ivo | B2: Araujo | C2: CENTROCAR - Centro de Equipamentos Mecânicos S.A. | D2: Olá Ivo, A CENTROCAR - Centro de Equipamentos Mecânicos S.A. mantém os clientes a trabalhar, e os comandos finais, de translação e de rotação das máquinas que assistem são o que fica parado quando um redutor está em falta. Fornecemos redutores industriais e móveis - helicoidais, cónicos, planetários, comandos de translação e rotação - a preços de revenda, 10 a 14 dias até Angola para as medidas em stock. A maioria dos distribuidores com quem trabalhamos mantém um pequeno stock das unidades que mais substituem, para resolver uma avaria na mesma semana em vez de esperar seis. Posso enviar a nossa gama e preços de revenda? | E2: Fornecimento de redutores para a CENTROCAR - Centro de Equipamentos Mecânicos S.A. | F2: ivo.araujo@centrocar.com | G2: General Manager Angola | H2: Angola | I2: Luanda | J2: Distributor | K2: A | L2: C026 | M2: Portuguese | N2: http://www.linkedin.com/in/ivo-araujo-9470b849 | O2: centrocar.com | P2: +351 22 002 9150 | Q2: 150 | R2: machinery | S2: Stocking terms and margin - lead with the commercial offer to the MD/GM, not the spec sheet | T2: HQ abroad (Portugal) - verify local buying authority | U2: Not contacted
A3: Luca | B3: Sassella | C3: E.A.T.S Metering Systems | D3: Olá Luca, A E.A.T.S Metering Systems mantém os clientes a trabalhar, e os redutores que acompanham os sistemas que fornecem são o que fica parado quando um redutor está em falta. Fornecemos redutores industriais e móveis - helicoidais, cónicos, planetários, comandos de translação e rotação - a preços de revenda, 10 a 14 dias até Angola para as medidas em stock. A maioria dos distribuidores com quem trabalhamos mantém um pequeno stock das unidades que mais substituem, para resolver uma avaria na mesma semana em vez de esperar seis. Posso enviar a nossa gama e preços de revenda? | E3: Fornecimento de redutores para a E.A.T.S Metering Systems | F3: luca.sassella@eats.ao | G3: Managing Director | H3: Angola | J3: Distributor | K3: A | L3: C044 | M3: Portuguese | N3: http://www.linkedin.com/in/luca-sassella-6b69765 | O3: eats.ao | P3: +244 931 878 469 | Q3: 9 | R3: oil & energy | S3: Stocking terms and margin - lead with the commercial offer to the MD/GM, not the spec sheet | U3: Not contacted
A4: Eduardo | B4: Fernandez | C4: ENCOM Lda. | D4: Olá Eduardo, A ENCOM Lda. mantém os clientes a trabalhar, e os redutores que os vossos clientes industriais vos pedem são o que fica parado quando um redutor está em falta. Fornecemos redutores industriais e móveis - helicoidais, cónicos, planetários, comandos de translação e rotação - a preços de revenda, 10 a 14 dias até Angola para as medidas em stock. A maioria dos distribuidores com quem trabalhamos mantém um pequeno stock das unidades que mais substituem, para resolver uma avaria na mesma semana em vez de esperar seis. Posso enviar a nossa gama e preços de revenda? | E4: Fornecimento de redutores para a ENCOM Lda. | F4: eduardo.fernandez@encom.it.ao | G4: Managing Director | H4: Angola | I4: Luanda | J4: Distributor | K4: A | L4: C045 | M4: Portuguese | N4: http://www.linkedin.com/in/edufernandez | O4: encom.it.ao | P4: +1 713-429-5084 | Q4: 24 | R4: oil & energy | S4: Stocking terms and margin - lead with the commercial offer to the MD/GM, not the spec sheet | U4: Not contacted
A5: Jose | B5: Santos | C5: ENERLINE, SA | D5: Olá Jose, A ENERLINE, SA mantém os clientes a trabalhar, e os redutores dos equipamentos que instalam e mantêm são o que fica parado quando um redutor está em falta. Fornecemos redutores industriais e móveis - helicoidais, cónicos, planetários, comandos de translação e rotação - a preços de revenda, 10 a 14 dias até Angola para as medidas em stock. A maioria dos distribuidores com quem trabalhamos mantém um pequeno stock das unidades que mais substituem, para resolver uma avaria na mesma semana em vez de esperar seis. Posso enviar a nossa gama e preços de revenda? | E5: Fornecimento de redutores para a ENERLINE, SA | F5: josesantos@enerline.ao | G5: General Manager | H5: Angola | I5: Luanda | J5: Distributor | K5: A | L5: C046 | M5: Portuguese | N5: http://www.linkedin.com/in/jose-santos-9193b9253 | O5: enerline.ao | Q5: 250 | R5: oil & energy | S5: Stocking terms and margin - lead with the commercial offer to the MD/GM, not the spec sheet | U5: Not contacted
A6: Jose | B6: Garrido | C6: Elecnor Group | D6: Olá Jose, A Elecnor Group mantém os clientes a trabalhar, e os accionamentos dos equipamentos de obra e das instalações que constroem são o que fica parado quando um redutor está em falta. Fornecemos redutores industriais e móveis - helicoidais, cónicos, planetários, comandos de translação e rotação - a preços de revenda, 10 a 14 dias até Angola para as medidas em stock. A maioria dos distribuidores com quem trabalhamos mantém um pequeno stock das unidades que mais substituem, para resolver uma avaria na mesma semana em vez de esperar seis. Posso enviar a nossa gama e preços de revenda? | E6: Fornecimento de redutores para a Elecnor Group | F6: jlgarrido@elecnor.com | G6: Director Geral Adjunto de Sucursal Angola | H6: Angola | I6: Luanda | J6: Distributor | K6: A | L6: C048 | M6: Portuguese | N6: http://www.linkedin.com/in/jose-luis-garrido-34110623 | O6: grupoelecnor.com | Q6: 29000 | R6: construction | S6: Stocking terms and margin - lead with the commercial offer to the MD/GM, not the spec sheet | T6: HQ abroad (Spain) - verify local buying authority | U6: Not contacted
A7: Januario | B7: Cuela | C7: GEA Group | D7: Olá Januario, A GEA Group mantém os clientes a trabalhar, e os redutores dos equipamentos de processo que instalam e assistem são o que fica parado quando um redutor está em falta. Fornecemos redutores industriais e móveis - helicoidais, cónicos, planetários, comandos de translação e rotação - a preços de revenda, 10 a 14 dias até Angola para as medidas em stock. A maioria dos distribuidores com quem trabalhamos mantém um pequeno stock das unidades que mais substituem, para resolver uma avaria na mesma semana em vez de esperar seis. Posso enviar a nossa gama e preços de revenda? | E7: Fornecimento de redutores para a GEA Group | F7: januario.cuela@gea.com | G7: Branch Manager Angola | H7: Angola | J7: Distributor | K7: A | L7: C055 | M7: Portuguese | N7: http://www.linkedin.com/in/januario-cuela-985a1538 | O7: gea.com | P7: +49 211 91360 | Q7: 20000 | R7: machinery | S7: Stocking terms and margin - lead with the commercial offer to the MD/GM, not the spec sheet | T7: HQ abroad (Germany) - verify local buying authority | U7: Not contacted
A8: Rayan | B8: Farhat | C8: Industryhub | D8: Olá Rayan, A Industryhub mantém os clientes a trabalhar, e os redutores que os vossos clientes industriais vos pedem são o que fica parado quando um redutor está em falta. Fornecemos redutores industriais e móveis - helicoidais, cónicos, planetários, comandos de translação e rotação - a preços de revenda, 10 a 14 dias até Angola para as medidas em stock. A maioria dos distribuidores com quem trabalhamos mantém um pequeno stock das unidades que mais substituem, para resolver uma avaria na mesma semana em vez de esperar seis. Posso enviar a nossa gama e preços de revenda? | E8: Fornecimento de redutores para a Industryhub | F8: rayan.farhat@industryhubangola.com | G8: Managing Director and Founder | H8: Angola | I8: Luanda | J8: Distributor | K8: A | L8: C063 | M8: Portuguese | N8: http://www.linkedin.com/in/rayan-farhat | O8: industryhubangola.com | Q8: 11 | R8: automotive | S8: Stocking terms and margin - lead with the commercial offer to the MD/GM, not the spec sheet | U8: Not contacted
A9: Nasim | B9: Kayali | C9: Mega Mecanix | D9: Olá Nasim, A Mega Mecanix mantém os clientes a trabalhar, e os redutores dos equipamentos industriais que fornecem são o que fica parado quando um redutor está em falta. Fornecemos redutores industriais e móveis - helicoidais, cónicos, planetários, comandos de translação e rotação - a preços de revenda, 10 a 14 dias até Angola para as medidas em stock. A maioria dos distribuidores com quem trabalhamos mantém um pequeno stock das unidades que mais substituem, para resolver uma avaria na mesma semana em vez de esperar seis. Posso enviar a nossa gama e preços de revenda? | E9: Fornecimento de redutores para a Mega Mecanix | F9: n.kayali@mecanixsal.com | G9: General Manager | H9: Angola | J9: Distributor | K9: A | L9: C074 | M9: Portuguese | N9: http://www.linkedin.com/in/nasim-kayali-0bbb2937 | O9: mecanixsal.com | P9: +961 5 950 866 | Q9: 19 | R9: machinery | S9: Stocking terms and margin - lead with the commercial offer to the MD/GM, not the spec sheet | U9: Not contacted
A10: Paulo | B10: Rodrigues | C10: Movicortes Angola | D10: Olá Paulo, A Movicortes Angola mantém os clientes a trabalhar, e os redutores das máquinas e equipamentos que comercializam são o que fica parado quando um redutor está em falta. Fornecemos redutores industriais e móveis - helicoidais, cónicos, planetários, comandos de translação e rotação - a preços de revenda, 10 a 14 dias até Angola para as medidas em stock. A maioria dos distribuidores com quem trabalhamos mantém um pequeno stock das unidades que mais substituem, para resolver uma avaria na mesma semana em vez de esperar seis. Posso enviar a nossa gama e preços de revenda? | E10: Fornecimento de redutores para a Movicortes Angola | F10: paulo.rodrigues@movicortes.pt | G10: General Manager | H10: Angola | I10: Luanda | J10: Distributor | K10: A | L10: C080 | M10: Portuguese | N10: http://www.linkedin.com/in/paulo-rodrigues-a35823164 | O10: movicortesangola.com | Q10: 7 | R10: machinery | S10: Stocking terms and margin - lead with the commercial offer to the MD/GM, not the spec sheet | U10: Not contacted
A11: Peter | B11: Mashangu | C11: Nampak | D11: Olá Peter, A Nampak mantém os clientes a trabalhar, e os accionamentos das prensas, transportadores e linhas de embalagem são o que fica parado quando um redutor está em falta. Fornecemos redutores industriais e móveis - helicoidais, cónicos, planetários, comandos de translação e rotação - a preços de revenda, 10 a 14 dias até Angola para as medidas em stock. A maioria dos distribuidores com quem trabalhamos mantém um pequeno stock das unidades que mais substituem, para resolver uma avaria na mesma semana em vez de esperar seis. Posso enviar a nossa gama e preços de revenda? | E11: Fornecimento de redutores para a Nampak | F11: peter.mashangu@nampak.com | G11: Managing Director | H11: Angola | I11: Luanda | J11: Distributor | K11: A | L11: C081 | M11: Portuguese | N11: http://www.linkedin.com/in/peter-mashangu-394611159 | O11: nampak.com | P11: +27 11 719 6300 | Q11: 2500 | R11: packaging & containers | S11: Stocking terms and margin - lead with the commercial offer to the MD/GM, not the spec sheet | T11: HQ abroad (South Africa) - verify local buying authority | U11: Not contacted
A12: Kitana | B12: Barbosa | C12: Nors Group | D12: Olá Kitana, A Nors Group mantém os clientes a trabalhar, e os comandos finais e caixas das máquinas e camiões que assistem no pós-venda são o que fica parado quando um redutor está em falta. Fornecemos redutores industriais e móveis - helicoidais, cónicos, planetários, comandos de translação e rotação - a preços de revenda, 10 a 14 dias até Angola para as medidas em stock. A maioria dos distribuidores com quem trabalhamos mantém um pequeno stock das unidades que mais substituem, para resolver uma avaria na mesma semana em vez de esperar seis. Posso enviar a nossa gama e preços de revenda? | E12: Fornecimento de redutores para a Nors Group | F12: kbarbosa@nors.com | G12: After Sales Director | H12: Angola | I12: Luanda | J12: Distributor | K12: A | L12: C083 | M12: Portuguese | N12: http://www.linkedin.com/in/kitana-barbosa-b3b58486 | O12: nors.com | P12: +351 22 615 0320 | Q12: 3200 | R12: automotive | S12: Stocking terms and margin - lead with the commercial offer to the MD/GM, not the spec sheet | T12: HQ abroad (Portugal) - verify local buying authority | U12: Not contacted
A13: Jean | B13: Rodrigues | C13: OG3S Mecanica Lda | D13: Olá Jean, A OG3S Mecanica Lda mantém os clientes a trabalhar, e os redutores dos equipamentos industriais que assistem são o que fica parado quando um redutor está em falta. Fornecemos redutores industriais e móveis - helicoidais, cónicos, planetários, comandos de translação e rotação - a preços de revenda, 10 a 14 dias até Angola para as medidas em stock. A maioria dos distribuidores com quem trabalhamos mantém um pequeno stock das unidades que mais substituem, para resolver uma avaria na mesma semana em vez de esperar seis. Posso enviar a nossa gama e preços de revenda? | E13: Fornecimento de redutores para a OG3S Mecanica Lda | F13: jean-philippe.rodrigues@og3s-mecanica.com | G13: Executive Managing Director | H13: Angola | J13: Distributor | K13: A | L13: C085 | M13: Portuguese | N13: http://www.linkedin.com/in/jean-philippe-rodrigues-a727b82b | O13: og3s-mecanica.com | Q13: 35 | R13: oil & energy | S13: Stocking terms and margin - lead with the commercial offer to the MD/GM, not the spec sheet | U13: Not contacted
A14: Luis | B14: Almeida | C14: SPIE Global Services Energy | D14: Olá Luis, A SPIE Global Services Energy mantém os clientes a trabalhar, e os redutores dos equipamentos rotativos que mantêm em operação são o que fica parado quando um redutor está em falta. Fornecemos redutores industriais e móveis - helicoidais, cónicos, planetários, comandos de translação e rotação - a preços de revenda, 10 a 14 dias até Angola para as medidas em stock. A maioria dos distribuidores com quem trabalhamos mantém um pequeno stock das unidades que mais substituem, para resolver uma avaria na mesma semana em vez de esperar seis. Posso enviar a nossa gama e preços de revenda? | E14: Fornecimento de redutores para a SPIE Global Services Energy | F14: l.almeida@spie.com | G14: Managing Director Angola & Mozambique | H14: Angola | I14: Luanda | J14: Distributor | K14: A | L14: C105 | M14: Portuguese | N14: http://www.linkedin.com/in/luis-ferreira-de-almeida-34495338 | O14: spie.com | P14: +33 1 34 41 81 81 | Q14: 5000 | R14: oil & energy | S14: Stocking terms and margin - lead with the commercial offer to the MD/GM, not the spec sheet | T14: HQ abroad (France) - verify local buying authority | U14: Not contacted
A15: Nicolas | B15: Monville | C15: TFE GROUP INC | D15: Olá Nicolas, A TFE GROUP INC mantém os clientes a trabalhar, e os redutores que os vossos clientes industriais vos pedem são o que fica parado quando um redutor está em falta. Fornecemos redutores industriais e móveis - helicoidais, cónicos, planetários, comandos de translação e rotação - a preços de revenda, 10 a 14 dias até Angola para as medidas em stock. A maioria dos distribuidores com quem trabalhamos mantém um pequeno stock das unidades que mais substituem, para resolver uma avaria na mesma semana em vez de esperar seis. Posso enviar a nossa gama e preços de revenda? | E15: Fornecimento de redutores para a TFE GROUP INC | F15: nicolas.monville@grouptfe.com | G15: Managing Director | H15: Angola | J15: Distributor | K15: A | L15: C119 | M15: Portuguese | N15: http://www.linkedin.com/in/nicolas-monville-411a6358 | O15: grouptfe.com | P15: +33 4 66 70 64 10 | Q15: 45 | R15: oil & energy | S15: Stocking terms and margin - lead with the commercial offer to the MD/GM, not the spec sheet | T15: HQ abroad (France) - verify local buying authority | U15: Not contacted
A16: Mathieu | B16: Wallach | C16: Welltec | D16: Olá Mathieu, A Welltec mantém os clientes a trabalhar, e os redutores e accionamentos dos guinchos e equipamentos de intervenção são o que fica parado quando um redutor está em falta. Fornecemos redutores industriais e móveis - helicoidais, cónicos, planetários, comandos de translação e rotação - a preços de revenda, 10 a 14 dias até Angola para as medidas em stock. A maioria dos distribuidores com quem trabalhamos mantém um pequeno stock das unidades que mais substituem, para resolver uma avaria na mesma semana em vez de esperar seis. Posso enviar a nossa gama e preços de revenda? | E16: Fornecimento de redutores para a Welltec | F16: mwallach@welltec.com | G16: Sales Director and General Manager, Southern Africa | H16: Angola | J16: Distributor | K16: A | L16: C132 | M16: Portuguese | N16: http://www.linkedin.com/in/mathieu-wallach-a9203a59 | O16: welltec.com | P16: +45 48 14 35 14 | Q16: 740 | R16: oil & energy | S16: Stocking terms and margin - lead with the commercial offer to the MD/GM, not the spec sheet | T16: HQ abroad (Denmark) - verify local buying authority | U16: Not contacted
A17: Favor | B17: Marebole | C17: Applied Metrology Services (Pty) Ltd. | D17: Hi Favor, Applied Metrology Services (Pty) Ltd. keeps its customers running, and the gearboxes on the process equipment you calibrate and service are what sit idle when a gearbox is on backorder. We supply industrial and mobile gearboxes - helical, bevel-helical, planetary, travel and swing drives - at trade pricing, 10 to 14 days into Botswana for stocked sizes. Most distributors we work with hold a small consignment of the units they move most, so a breakdown becomes a same-week fix instead of a six-week import. Can I send our range and dealer pricing? | E17: Gearbox supply for Applied Metrology Services (Pty) Ltd. | F17: favor@appliedmetrology.co.za | G17: Managing Director | H17: Botswana | J17: Distributor | K17: A | L17: C008 | M17: English | N17: http://www.linkedin.com/in/favor-marebole-a060559 | O17: appliedmetrology.co.za | P17: +27 11 568 0386 | Q17: 12 | R17: machinery | S17: Stocking terms and margin - lead with the commercial offer to the MD/GM, not the spec sheet | T17: HQ abroad (South Africa) - verify local buying authority | U17: Not contacted
A18: Bofedile | B18: Moeti | C18: Bofedile Tech Services (Pty) Ltd | D18: Hi Bofedile, Bofedile Tech Services (Pty) Ltd keeps its customers running, and the gearboxes on the mining and industrial equipment you supply are what sit idle when a gearbox is on backorder. We supply industrial and mobile gearboxes - helical, bevel-helical, planetary, travel and swing drives - at trade pricing, 10 to 14 days into Botswana for stocked sizes. Most distributors we work with hold a small consignment of the units they move most, so a breakdown becomes a same-week fix instead of a six-week import. Can I send our range and dealer pricing? | E18: Gearbox supply for Bofedile Tech Services (Pty) Ltd | F18: bmoeti@bts-bw.com | G18: Managing Director | H18: Botswana | I18: Gaborone | J18: Distributor | K18: A | L18: C022 | M18: English | N18: http://www.linkedin.com/in/bofedile-moeti-6b1b0447 | O18: bts-bw.com | Q18: 6 | R18: industrial automation | S18: Stocking terms and margin - lead with the commercial offer to the MD/GM, not the spec sheet | U18: Not contacted
A19: Wessel | B19: Wessels | C19: Coastal Hire | D19: Hi Wessel, Coastal Hire keeps its customers running, and the gearboxes on the plant in your hire fleet are what sit idle when a gearbox is on backorder. We supply industrial and mobile gearboxes - helical, bevel-helical, planetary, travel and swing drives - at trade pricing, 10 to 14 days into Botswana for stocked sizes. Most distributors we work with hold a small consignment of the units they move most, so a breakdown becomes a same-week fix instead of a six-week import. Can I send our range and dealer pricing? | E19: Gearbox supply for Coastal Hire | F19: wessel@coastalhire.co.za | G19: Managing Director | H19: Botswana | J19: Distributor | K19: A | L19: C033 | M19: English | N19: http://www.linkedin.com/in/wessel-wessels-086569146 | O19: coastalhire.co.za | P19: +27 10 158 0525 | Q19: 260 | R19: construction / equipment hire | S19: Stocking terms and margin - lead with the commercial offer to the MD/GM, not the spec sheet | T19: HQ abroad (South Africa) - verify local buying authority | U19: Not contacted
A20: Tichaona | B20: Ndhlovu | C20: Delswiz Manufacturing (Pty) Limited | D20: Hi Tichaona, Delswiz Manufacturing (Pty) Limited keeps its customers running, and the gearboxes for the conveyor systems and idlers you fabricate are what sit idle when a gearbox is on backorder. We supply industrial and mobile gearboxes - helical, bevel-helical, planetary, travel and swing drives - at trade pricing, 10 to 14 days into Botswana for stocked sizes. Most distributors we work with hold a small consignment of the units they move most, so a breakdown becomes a same-week fix instead of a six-week import. Can I send our range and dealer pricing? | E20: Gearbox supply for Delswiz Manufacturing (Pty) Limited | F20: tndhlovu@delswizgroup.com | G20: Managing Director | H20: Botswana | I20: Gaborone | J20: Distributor | K20: A | L20: C042 | M20: English | N20: http://www.linkedin.com/in/tichaona-ndhlovu-93212b141 | O20: delswizgroup.com | P20: +971 55 157 9261 | Q20: 26 | R20: mining & metals | S20: Stocking terms and margin - lead with the commercial offer to the MD/GM, not the spec sheet | U20: Not contacted
A21: Clayton | B21: Davis | C21: HANSA-FLEX AG | D21: Hi Clayton, HANSA-FLEX AG keeps its customers running, and the gearboxes that sit alongside the hydraulics you already supply are what sit idle when a gearbox is on backorder. We supply industrial and mobile gearboxes - helical, bevel-helical, planetary, travel and swing drives - at trade pricing, 10 to 14 days into Botswana for stocked sizes. Most distributors we work with hold a small consignment of the units they move most, so a breakdown becomes a same-week fix instead of a six-week import. Can I send our range and dealer pricing? | E21: Gearbox supply for HANSA-FLEX AG | F21: clayton.davis@hansa-flex.com | G21: General Manager | H21: Botswana | J21: Distributor | K21: A | L21: C058 | M21: English | N21: http://www.linkedin.com/in/clayton-davis-a18a377b | O21: hansa-flex.de | P21: +49 42 1489070 | Q21: 5200 | R21: machinery / hydraulics | S21: Stocking terms and margin - lead with the commercial offer to the MD/GM, not the spec sheet | T21: HQ abroad (Germany) - verify local buying authority | U21: Not contacted
A22: Zayd | B22: Bhoyroo | C22: Impex Group | D22: Hi Zayd, Impex Group keeps its customers running, and the industrial and automotive gearboxes your counter customers ask for are what sit idle when a gearbox is on backorder. We supply industrial and mobile gearboxes - helical, bevel-helical, planetary, travel and swing drives - at trade pricing, 10 to 14 days into Botswana for stocked sizes. Most distributors we work with hold a small consignment of the units they move most, so a breakdown becomes a same-week fix instead of a six-week import. Can I send our range and dealer pricing? | E22: Gearbox supply for Impex Group | F22: zayd@impex.co.bw | G22: Assistant General Manager | H22: Botswana | J22: Distributor | K22: A | L22: C062 | M22: English | N22: http://www.linkedin.com/in/zayd-bhoyroo-41419b161 | O22: impex.co.bw | Q22: 26 | R22: automotive / wholesale | S22: Stocking terms and margin - lead with the commercial offer to the MD/GM, not the spec sheet | U22: Not contacted
A23: Sonny | B23: Morekisi | C23: Komatsu Africa Holdings (Pty) Ltd | D23: Hi Sonny, Komatsu Africa Holdings (Pty) Ltd keeps its customers running, and your customers' excavator final drives, travel and swing drives are what sit idle when a gearbox is on backorder. We supply industrial and mobile gearboxes - helical, bevel-helical, planetary, travel and swing drives - at trade pricing, 10 to 14 days into Botswana for stocked sizes. Most distributors we work with hold a small consignment of the units they move most, so a breakdown becomes a same-week fix instead of a six-week import. Can I send our range and dealer pricing? | E23: Gearbox supply for Komatsu Africa Holdings (Pty) Ltd | F23: sonnym@komatsu.co.za | G23: Branch Manager | H23: Botswana | J23: Distributor | K23: A | L23: C066 | M23: English | N23: http://www.linkedin.com/in/sonny-morekisi-9b921043 | O23: komatsu.co.za | Q23: 360 | R23: machinery | S23: Stocking terms and margin - lead with the commercial offer to the MD/GM, not the spec sheet | T23: HQ abroad (South Africa) - verify local buying authority | U23: Not contacted
A24: Donovan | B24: Lendrum | C24: Rotating Solutions Botswana | D24: Hi Donovan, Rotating Solutions Botswana keeps its customers running, and the gearboxes that sit alongside the bearings and pumps you already distribute are what sit idle when a gearbox is on backorder. We supply industrial and mobile gearboxes - helical, bevel-helical, planetary, travel and swing drives - at trade pricing, 10 to 14 days into Botswana for stocked sizes. Most distributors we work with hold a small consignment of the units they move most, so a breakdown becomes a same-week fix instead of a six-week import. Can I send our range and dealer pricing? | E24: Gearbox supply for Rotating Solutions Botswana | F24: donovan@rotatingsolutions.co.bw | G24: Sales Director | H24: Botswana | I24: Gaborone | J24: Distributor | K24: A | L24: C100 | M24: English | N24: http://www.linkedin.com/in/donovan-lendrum-906a6352 | O24: rotatingsolutions.co.bw | Q24: 2 | R24: industrial supply / bearings and lubricants | S24: Stocking terms and margin - lead with the commercial offer to the MD/GM, not the spec sheet | U24: Not contacted
A25: Tshegofatso | B25: Mosweu | C25: SPTC | D25: Hi Tshegofatso, Most gearbox spend sits with a single supplier on long lead times. That works until the unit is on backorder - and at SPTC that means the gearboxes that pair with the electrical equipment you supply. We supply helical, bevel-helical and planetary gearboxes and drop-in replacements for SEW-Eurodrive, Flender, Bonfiglioli and David Brown - 10 to 14 days into Botswana for stocked sizes, 4 to 6 weeks made to order, with rebuild-on-exchange. No switching required. Quote us against your current source and see where we land. What do you need from us for vendor registration? | E25: Second source for gearbox spares - SPTC | F25: tshegofatso@sptc.com.sa | G25: Assistant Manager Procurement | H25: Botswana | J25: Distributor | K25: A | L25: C106 | M25: English | N25: http://www.linkedin.com/in/tshegofatso-mosweu-783017a1 | O25: sptc.com.sa | P25: +966 13 814 4624 | Q25: 320 | R25: electrical/electronic manufacturing | S25: Stocking terms and margin - lead with the commercial offer to the MD/GM, not the spec sheet | T25: HQ abroad (Saudi Arabia) - verify local buying authority | U25: Not contacted
A26: Justice | B26: Moilwa | C26: ZISMO Engineering (Pty) Ltd. | D26: Hi Justice, ZISMO Engineering (Pty) Ltd. keeps its customers running, and the gearboxes that pair with the motors and drives you already rebuild are what sit idle when a gearbox is on backorder. We supply industrial and mobile gearboxes - helical, bevel-helical, planetary, travel and swing drives - at trade pricing, 10 to 14 days into Botswana for stocked sizes. Most distributors we work with hold a small consignment of the units they move most, so a breakdown becomes a same-week fix instead of a six-week import. Can I send our range and dealer pricing? | E26: Gearbox supply for ZISMO Engineering (Pty) Ltd. | F26: jmoilwa@zismoengineering.com | G26: Managing Director | H26: Botswana | I26: Gaborone | J26: Distributor | K26: A | L26: C136 | M26: English | N26: http://www.linkedin.com/in/justice-moilwa-859595ba | O26: zismoengineeing.com | P26: +267 393 2711 | Q26: 58 | R26: electrical/electronic manufacturing | S26: Stocking terms and margin - lead with the commercial offer to the MD/GM, not the spec sheet | U26: Not contacted
A27: Michael | B27: Bentley | C27: ACTION AUTO ZAMBIA | D27: Hi Michael, ACTION AUTO ZAMBIA keeps its customers running, and the drivetrain and PTO gearboxes on the vehicles you support are what sit idle when a gearbox is on backorder. We supply industrial and mobile gearboxes - helical, bevel-helical, planetary, travel and swing drives - at trade pricing, 10 to 14 days into Zambia for stocked sizes. Most distributors we work with hold a small consignment of the units they move most, so a breakdown becomes a same-week fix instead of a six-week import. Can I send our range and dealer pricing? | E27: Gearbox supply for ACTION AUTO ZAMBIA | F27: m.bentley@actionautozambia.com | G27: Managing Director | H27: Zambia | J27: Distributor | K27: A | L27: C002 | M27: English | N27: http://www.linkedin.com/in/michael-bentley-69240073 | O27: actionautozambia.com | Q27: 54 | R27: automotive | S27: Stocking terms and margin - lead with the commercial offer to the MD/GM, not the spec sheet | U27: Not contacted
A28: Sajad | B28: Ahmed | C28: Access Energy Solutions Pty Ltd | D28: Hi Sajad, Access Energy Solutions Pty Ltd keeps its customers running, and the gearboxes on the plant and energy equipment you supply are what sit idle when a gearbox is on backorder. We supply industrial and mobile gearboxes - helical, bevel-helical, planetary, travel and swing drives - at trade pricing, 10 to 14 days into Zambia for stocked sizes. Most distributors we work with hold a small consignment of the units they move most, so a breakdown becomes a same-week fix instead of a six-week import. Can I send our range and dealer pricing? | E28: Gearbox supply for Access Energy Solutions Pty Ltd | F28: sajad@accessenergys.com | G28: MD | H28: Zambia | J28: Distributor | K28: A | L28: C004 | M28: English | N28: http://www.linkedin.com/in/sajad-ahmed-2ba5b5112 | O28: accessenergys.com | Q28: 4 | R28: environmental services | S28: Stocking terms and margin - lead with the commercial offer to the MD/GM, not the spec sheet | U28: Not contacted
A29: Dirk | B29: Wet | C29: BIA GROUP | D29: Hi Dirk, BIA GROUP keeps its customers running, and the final drives, travel and swing drives on the machines you support are what sit idle when a gearbox is on backorder. We supply industrial and mobile gearboxes - helical, bevel-helical, planetary, travel and swing drives - at trade pricing, 10 to 14 days into Zambia for stocked sizes. Most distributors we work with hold a small consignment of the units they move most, so a breakdown becomes a same-week fix instead of a six-week import. Can I send our range and dealer pricing? | E29: Gearbox supply for BIA GROUP | F29: dirk.dewet@biagroup.com | G29: Project Operation Manager | H29: Zambia | I29: Lusaka | J29: Distributor | K29: A | L29: C012 | M29: English | N29: http://www.linkedin.com/in/dirk-de-wet-8969b189 | O29: biagroup.com | P29: +32 2 689 28 11 | Q29: 1300 | R29: machinery | S29: Stocking terms and margin - lead with the commercial offer to the MD/GM, not the spec sheet | T29: HQ abroad (Mauritius) - verify local buying authority | U29: Not contacted
A30: Cobus | B30: Potgieter | C30: BL&D Plant Hire & Sales | D30: Hi Cobus, BL&D Plant Hire & Sales keeps its customers running, and the gearboxes on the plant in your hire and sales fleet are what sit idle when a gearbox is on backorder. We supply industrial and mobile gearboxes - helical, bevel-helical, planetary, travel and swing drives - at trade pricing, 10 to 14 days into Zambia for stocked sizes. Most distributors we work with hold a small consignment of the units they move most, so a breakdown becomes a same-week fix instead of a six-week import. Can I send our range and dealer pricing? | E30: Gearbox supply for BL&D Plant Hire & Sales | F30: cobus@bldequipment.com | G30: Branch Manager | H30: Zambia | J30: Distributor | K30: A | L30: C013 | M30: English | N30: http://www.linkedin.com/in/cobus-potgieter-68204494 | O30: bldequipment.com | Q30: 76 | R30: machinery | S30: Stocking terms and margin - lead with the commercial offer to the MD/GM, not the spec sheet | U30: Not contacted
A31: Samson | B31: Chingozho | C31: Bell Equipment Mining & Construction | D31: Hi Samson, Bell Equipment Mining & Construction keeps its customers running, and the drivetrains and hubs on the ADTs you support are what sit idle when a gearbox is on backorder. We supply industrial and mobile gearboxes - helical, bevel-helical, planetary, travel and swing drives - at trade pricing, 10 to 14 days into Zambia for stocked sizes. Most distributors we work with hold a small consignment of the units they move most, so a breakdown becomes a same-week fix instead of a six-week import. Can I send our range and dealer pricing? | E31: Gearbox supply for Bell Equipment Mining & Construction | F31: samson.chingozho@bellequipment.com | G31: Managing Director | H31: Zambia | J31: Distributor | K31: A | L31: C020 | M31: English | N31: http://www.linkedin.com/in/samson-chingozho-b584a212 | O31: bellequipment.com | P31: +27 35 907 9111 | Q31: 3500 | R31: machinery | S31: Stocking terms and margin - lead with the commercial offer to the MD/GM, not the spec sheet | T31: HQ abroad (South Africa) - verify local buying authority | U31: Not contacted
A32: Bevin | B32: Samwata | C32: Blumaq, S.A. | D32: Hi Bevin, Blumaq, S.A. keeps its customers running, and the final drives and travel drives your customers order most are what sit idle when a gearbox is on backorder. We supply industrial and mobile gearboxes - helical, bevel-helical, planetary, travel and swing drives - at trade pricing, 10 to 14 days into Zambia for stocked sizes. Most distributors we work with hold a small consignment of the units they move most, so a breakdown becomes a same-week fix instead of a six-week import. Can I send our range and dealer pricing? | E32: Gearbox supply for Blumaq, S.A. | F32: bevin.samwata@blumaq.com | G32: Branch Manager | H32: Zambia | I32: Kitwe | J32: Distributor | K32: A | L32: C021 | M32: English | N32: http://www.linkedin.com/in/bevin-samwata-76765a64 | O32: blumaq.com | P32: +34 964 69 70 30 | Q32: 250 | R32: machinery | S32: Stocking terms and margin - lead with the commercial offer to the MD/GM, not the spec sheet | T32: HQ abroad (Spain) - verify local buying authority | U32: Not contacted
A33: Henry | B33: Kapesa | C33: Bordertec Limited | D33: Hi Henry, Bordertec Limited keeps its customers running, and the gearboxes your industrial customers ask you to source are what sit idle when a gearbox is on backorder. We supply industrial and mobile gearboxes - helical, bevel-helical, planetary, travel and swing drives - at trade pricing, 10 to 14 days into Zambia for stocked sizes. Most distributors we work with hold a small consignment of the units they move most, so a breakdown becomes a same-week fix instead of a six-week import. Can I send our range and dealer pricing? | E33: Gearbox supply for Bordertec Limited | F33: henry@bordertecltd.com | G33: Managing Director | H33: Zambia | J33: Distributor | K33: A | L33: C023 | M33: English | N33: http://www.linkedin.com/in/henry-kapesa-044b16aa | O33: bordertec.co.zm | Q33: 5 | R33: management consulting | S33: Stocking terms and margin - lead with the commercial offer to the MD/GM, not the spec sheet | U33: Not contacted
A34: Jinu | B34: Raj | C34: DGC AFRICA | D34: Hi Jinu, DGC AFRICA keeps its customers running, and the gearboxes on the industrial plant you inspect and maintain are what sit idle when a gearbox is on backorder. We supply industrial and mobile gearboxes - helical, bevel-helical, planetary, travel and swing drives - at trade pricing, 10 to 14 days into Zambia for stocked sizes. Most distributors we work with hold a small consignment of the units they move most, so a breakdown becomes a same-week fix instead of a six-week import. Can I send our range and dealer pricing? | E34: Gearbox supply for DGC AFRICA | F34: jinu@dgc-africa.com | G34: General Manager | H34: Zambia | J34: Distributor | K34: A | L34: C037 | M34: English | N34: http://www.linkedin.com/in/jinu-raj-b51a2b15a | O34: dgc-africa.com | P34: +27 16 421 3720 | Q34: 200 | R34: mining & metals | S34: Stocking terms and margin - lead with the commercial offer to the MD/GM, not the spec sheet | T34: HQ abroad (South Africa) - verify local buying authority | U34: Not contacted
A35: Gregory | B35: Gavazzi | C35: Doppio Mining Equipment | D35: Hi Gregory, Doppio Mining Equipment keeps its customers running, and the gearboxes your mining equipment customers ask for are what sit idle when a gearbox is on backorder. We supply industrial and mobile gearboxes - helical, bevel-helical, planetary, travel and swing drives - at trade pricing, 10 to 14 days into Zambia for stocked sizes. Most distributors we work with hold a small consignment of the units they move most, so a breakdown becomes a same-week fix instead of a six-week import. Can I send our range and dealer pricing? | E35: Gearbox supply for Doppio Mining Equipment | F35: greg@doppioequipment.com | G35: Managing Director | H35: Zambia | J35: Distributor | K35: A | L35: C043 | M35: English | N35: http://www.linkedin.com/in/gregory-gavazzi-97ba9713a | O35: doppioequipment.com | Q35: 4 | R35: mining & metals | S35: Stocking terms and margin - lead with the commercial offer to the MD/GM, not the spec sheet | U35: Not contacted
A36: Chongo | B36: Mumba | C36: Hebei Aojin Machinery Co.,Ltd. | D36: Hi Chongo, Hebei Aojin Machinery Co.,Ltd. keeps its customers running, and the gearboxes on the machinery you bring into the market are what sit idle when a gearbox is on backorder. We supply industrial and mobile gearboxes - helical, bevel-helical, planetary, travel and swing drives - at trade pricing, 10 to 14 days into Zambia for stocked sizes. Most distributors we work with hold a small consignment of the units they move most, so a breakdown becomes a same-week fix instead of a six-week import. Can I send our range and dealer pricing? | E36: Gearbox supply for Hebei Aojin Machinery Co.,Ltd. | F36: chongom@aoj-pump.com | G36: Technical Sales Manager | H36: Zambia | J36: Distributor | K36: A | L36: C059 | M36: English | N36: http://www.linkedin.com/in/chongo-mumba-13295520 | O36: aoj-pump.com | P36: +86 311 8880 2472 | Q36: 150 | R36: machinery | S36: Stocking terms and margin - lead with the commercial offer to the MD/GM, not the spec sheet | T36: HQ abroad (China) - verify local buying authority | U36: Not contacted
A37: Arne | B37: Thorkildsen | C37: Hitachi Construction Machinery | D37: Hi Arne, Hitachi Construction Machinery keeps its customers running, and the travel and swing drives on the excavators you support are what sit idle when a gearbox is on backorder. We supply industrial and mobile gearboxes - helical, bevel-helical, planetary, travel and swing drives - at trade pricing, 10 to 14 days into Zambia for stocked sizes. Most distributors we work with hold a small consignment of the units they move most, so a breakdown becomes a same-week fix instead of a six-week import. Can I send our range and dealer pricing? | E37: Gearbox supply for Hitachi Construction Machinery | F37: arne.thorkildsen@hcmaf.com | G37: Branch Operations Manager | H37: Zambia | J37: Distributor | K37: A | L37: C060 | M37: English | N37: http://www.linkedin.com/in/arne-thorkildsen-336b2b82 | O37: hitachicm.com | P37: +81 358-26-8100 | Q37: 26000 | R37: machinery | S37: Stocking terms and margin - lead with the commercial offer to the MD/GM, not the spec sheet | T37: HQ abroad (Japan) - verify local buying authority | U37: Not contacted
A38: Henri | B38: Wassink | C38: Liebherr Group | D38: Hi Henri, Liebherr Group keeps its customers running, and the final and travel drives on the mining machines you support are what sit idle when a gearbox is on backorder. We supply industrial and mobile gearboxes - helical, bevel-helical, planetary, travel and swing drives - at trade pricing, 10 to 14 days into Zambia for stocked sizes. Most distributors we work with hold a small consignment of the units they move most, so a breakdown becomes a same-week fix instead of a six-week import. Can I send our range and dealer pricing? | E38: Gearbox supply for Liebherr Group | F38: hendrik.wassink@liebherr.com | G38: Managing Director - Administration | H38: Zambia | J38: Distributor | K38: A | L38: C070 | M38: English | N38: http://www.linkedin.com/in/henri-wassink-60322140 | O38: liebherr.com | P38: +49 735 1410 | Q38: 54000 | R38: machinery | S38: Stocking terms and margin - lead with the commercial offer to the MD/GM, not the spec sheet | T38: HQ abroad (Germany) - verify local buying authority | U38: Not contacted
A39: Yoginder | B39: Singh | C39: R A Consulting Services (RACS) | D39: Hi Yoginder, R A Consulting Services (RACS) keeps its customers running, and the gearboxes on the plant that passes through your workshop are what sit idle when a gearbox is on backorder. We supply industrial and mobile gearboxes - helical, bevel-helical, planetary, travel and swing drives - at trade pricing, 10 to 14 days into Zambia for stocked sizes. Most distributors we work with hold a small consignment of the units they move most, so a breakdown becomes a same-week fix instead of a six-week import. Can I send our range and dealer pricing? | E39: Gearbox supply for R A Consulting Services (RACS) | F39: yoginder@racsafrica.com | G39: Workshop Manager | H39: Zambia | J39: Distributor | K39: A | L39: C098 | M39: English | N39: http://www.linkedin.com/in/yoginder-singh-944003180 | O39: racsafrica.com | P39: +267 393 9773 | Q39: 87 | R39: information technology & services | S39: Stocking terms and margin - lead with the commercial offer to the MD/GM, not the spec sheet | U39: Not contacted
A40: Simon | B40: Kazunda | C40: SAFE KAHYA Limited | D40: Hi Simon, SAFE KAHYA Limited keeps its customers running, and the gearboxes your industrial customers ask you to source are what sit idle when a gearbox is on backorder. We supply industrial and mobile gearboxes - helical, bevel-helical, planetary, travel and swing drives - at trade pricing, 10 to 14 days into Zambia for stocked sizes. Most distributors we work with hold a small consignment of the units they move most, so a breakdown becomes a same-week fix instead of a six-week import. Can I send our range and dealer pricing? | E40: Gearbox supply for SAFE KAHYA Limited | F40: simon.kazunda@safekahya.com | G40: Managing Director | H40: Zambia | J40: Distributor | K40: A | L40: C103 | M40: English | N40: http://www.linkedin.com/in/simon-kazunda-46655b21 | O40: safekahya.com | Q40: 1 | R40: electrical/electronic manufacturing | S40: Stocking terms and margin - lead with the commercial offer to the MD/GM, not the spec sheet | U40: Not contacted
...

Sheet Read me
A1: Gearbox Leads - Batch 1
A3: What this is
A4: 200 contacts in Botswana, Zambia and Angola who buy or resell industrial gearboxes.
A5: Every one has an Apollo-verified work email. Sourced 28 July 2026.
A7: The emails
A8: 136 companies, 136 different emails - one written for each company.
A9: Each email names that company's own equipment. First Quantum's mentions the Kansanshi and
A10: Sentinel mill and conveyor drives. Chilanga Cement's mentions the raw mill, kiln and clinker
A11: conveyors. Nors Group's mentions the final drives on the machines they service.
A13: On the Leads tab, column K holds the email for that person with their name already written in.
A14: It is ready to send: copy the cell, paste into your mail client, add your signature.
A15: The Mails tab shows the same emails once per company, if you prefer to read them that way.
... A48: Batch 4 - Namibia, DRC Copperbelt, Mozambique, Zimbabwe
