Workbook

Sheet Summary
A1: Gearbox Leads - Batch 1
A2: Botswana | Zambia | Angola - every contact has an Apollo-verified work email
A4: By country
A5: Country | B5: Contacts
A6: Botswana | B6: =COUNTIF(Leads!$E$2:$E$201,A6)
A7: Zambia | B7: =COUNTIF(Leads!$E$2:$E$201,A7)
A8: Angola | B8: =COUNTIF(Leads!$E$2:$E$201,A8)
A9: Total | B9: =SUM(B6:B8)
A11: By segment
A12: Segment | B12: Contacts
A13: Distributor | B13: =COUNTIF(Leads!$G$2:$G$201,A13)
A14: Mining | B14: =COUNTIF(Leads!$G$2:$G$201,A14)
A15: Mining/Construction | B15: =COUNTIF(Leads!$G$2:$G$201,A15)
A16: Agro/Cement | B16: =COUNTIF(Leads!$G$2:$G$201,A16)
A17: Agro/Food | B17: =COUNTIF(Leads!$G$2:$G$201,A17)
A18: Energy/Oil&Gas | B18: =COUNTIF(Leads!$G$2:$G$201,A18)
A19: Energy/Logistics | B19: =COUNTIF(Leads!$G$2:$G$201,A19)
A20: Total | B20: =SUM(B13:B19)
A22: By priority tier - work A first
A23: Tier | B23: What it is | C23: Contacts
A24: A | B24: Distributors and dealers - resell, stock, buy repeatedly | C24: =COUNTIF(Leads!$H$2:$H$201,A24)
A25: B | B25: Mining - highest spend, downtime costs them per hour | C25: =COUNTIF(Leads!$H$2:$H$201,A25)
A26: C | B26: Other end users - agro, cement, energy, logistics | C26: =COUNTIF(Leads!$H$2:$H$201,A26)
A27: Total | C27: =SUM(C24:C26)
A29: Send language
A30: Language | B30: Contacts
A31: English | B31: =COUNTIF(Leads!$K$2:$K$201,A31)
A32: Portuguese | B32: =COUNTIF(Leads!$K$2:$K$201,A32)
A33: Angola is Portuguese. Send those in English and they are wasted.
A35: Outreach progress - fills in as you update the Status column
A36: Status | B36: Contacts
A37: Not contacted | B37: =COUNTIF(Leads!$S$2:$S$201,A37)
A38: Emailed | B38: =COUNTIF(Leads!$S$2:$S$201,A38)
A39: Follow-up sent | B39: =COUNTIF(Leads!$S$2:$S$201,A39)
A40: Replied | B40: =COUNTIF(Leads!$S$2:$S$201,A40)
A41: Meeting booked | B41: =COUNTIF(Leads!$S$2:$S$201,A41)
A42: Quoted | B42: =COUNTIF(Leads!$S$2:$S$201,A42)
A43: Not interested | B43: =COUNTIF(Leads!$S$2:$S$201,A43)
A44: Bounced | B44: =COUNTIF(Leads!$S$2:$S$201,A44)
A45: Reply rate | B45: =IFERROR(COUNTIF(Leads!$S$2:$S$201,"Replied")/MAX(1,COUNTIF(Leads!$S$2:$S$201,"Emailed")+COUNTIF(Leads!$S$2:$S$201,"Follow-up sent")+COUNTIF(Leads!$S$2:$S$201,"Replied")),0)

Sheet Mails
A1: Emails by target group
A2: One email per group of similar companies. Filter the Mail column on the Leads tab to send one group at a time.
A3: Replace every [BRACKET] with your own details before sending. {First}, {Company} and {Country} are merge fields - your mail tool fills them from the Leads tab.
A5: Mail | B5: Target group | C5: Language | D5: Contacts | E5: Typical companies | F5: Subject line | G5: Email body | H5: Follow-up, day 4
A6: M1 | B6: Equipment & parts dealers | C6: English | D6: =COUNTIF(Leads!$I$2:$I$201,A6) | E6: Komatsu, Bell Equipment, Hitachi, Liebherr, Barloworld, Blumaq, BIA Group, Coastal Hire, Saro Agro, Action Auto, Impex | F6: Gearbox spares for the machines you support | G6: Hi {First}, {Company} keeps your customers' machines running - and a gearbox on backorder is what stops one for six weeks. We supply industrial and mobile gearboxes: [helical, bevel-helical, planetary, travel and swing drives]. Stock on the shelf, [X] days into {Country}. Most dealers we work with hold a small consignment of the units they replace most often, so a breakdown becomes a same-week fix instead of a six-week import. Can I send our range and dealer pricing? [YOUR NAME] [YOUR COMPANY] | [PHONE] | H6: Did the range list reach you? Happy to quote the three units you replace most often - no obligation.
A7: M2 | B7: Industrial & engineering suppliers | C7: English | D7: =COUNTIF(Leads!$I$2:$I$201,A7) | E7: ZISMO Engineering, Rotating Solutions, Sulzer, HANSA-FLEX, Selected Supplies, SKMS, Younique Engineering, Delswiz, DGC Africa, Bordertec, Access Energy | F7: Gearbox supply partner for {Company} | G7: Hi {First}, When your client's drive fails, the job is won or lost on how fast you can put a gearbox on site. We supply [helical, bevel-helical, worm and planetary] units, plus made-to-drawing replacements for [SEW, Flender, Bonfiglioli, Nord] - [X] days into {Country}, at trade pricing for resellers. We supply through local partners, not around them. The client stays yours. Worth a short call? I can send the range and trade terms first. [YOUR NAME] [YOUR COMPANY] | [PHONE] | H7: Any drive enquiries open right now? Send me the nameplate and I'll come back with price and lead time the same day.
A8: M3 | B8: Distribuidores e fornecedores industriais | C8: Portuguese | D8: =COUNTIF(Leads!$I$2:$I$201,A8) | E8: Centrocar, Nors Group, OG3S Mecanica, Movicortes, Mega Mecanix, GEA Group, Industryhub, ENCOM, ENERLINE, Elecnor, SPIE | F8: Redutores para as maquinas que a {Company} assiste | G8: Ola {First}, A {Company} mantem as maquinas dos vossos clientes a trabalhar - e um redutor em falta e o que para uma maquina durante seis semanas. Fornecemos redutores industriais e moveis: [helicoidais, conicos, planetarios, comandos de translacao e rotacao]. Stock disponivel, [X] dias ate Angola. A maioria dos distribuidores com quem trabalhamos mantem um pequeno stock das unidades que mais substituem - assim uma avaria resolve-se na mesma semana. Posso enviar a nossa gama e precos de revenda? [SEU NOME] [SUA EMPRESA] | [TELEFONE] | H8: Recebeu a nossa gama? Posso orcamentar as tres unidades que mais substituem, sem compromisso.
A9: M4 | B9: Mining - maintenance & reliability | C9: English | D9: =COUNTIF(Leads!$I$2:$I$201,A9) | E9: First Quantum, Konkola Copper, Mopani, Debswana, Morupule Coal, Sandfire, Barrick, Minergy, Barminco, African Mining Services | F9: Gearbox lead times for {Company} | G9: Hi {First}, A failed mill or conveyor drive is measured in dollars an hour, and the usual answer from suppliers is "twelve weeks". We hold [helical, bevel-helical and planetary] gearboxes and supply drop-in replacements for [SEW, Flender, David Brown] - [X] days into {Country}, with rebuild-on-exchange. No pitch needed: send me the units on your critical spares list and I'll come back with price and lead time, so you have a second source on file before you need one. [YOUR NAME] [YOUR COMPANY] | [PHONE] | H9: Even one nameplate photo is enough - I'll quote it so you know where we sit on price and lead time.
A10: M5 | B10: Procurement & supply chain | C10: English | D10: =COUNTIF(Leads!$I$2:$I$201,A10) | E10: Procurement, purchasing, contracts and supply-chain contacts across the mining, agro, cement and energy accounts | F10: Second source for gearbox spares | G10: Hi {First}, Most gearbox spend in {Country} sits with one supplier on long lead times. That works until the unit is on backorder. We supply [helical, bevel-helical and planetary] gearboxes and drop-in replacements for [SEW, Flender, David Brown] - [X] days into {Country}, with rebuild-on-exchange. Happy to simply be quoted against as a second source. No switching required. Send me your gearbox line items and I'll return prices and lead times. What do you need from us to get on the vendor list? [YOUR NAME] [YOUR COMPANY] | [PHONE] | H10: Shall I send our company profile and compliance documents for vendor registration?
A11: M6 | B11: Mineracao e construcao - tecnico | C11: Portuguese | D11: =COUNTIF(Leads!$I$2:$I$201,A11) | E11: Sociedade Mineira de Catoca, Endiama, Grupo Omatapalo, Marlin Natural Stones, PROMETIM, Equipment & Controls, ESA, Metalosul, TechnipFMC | F11: Prazos de entrega de redutores para a {Company} | G11: Ola {First}, Uma avaria num redutor de moinho ou transportador conta-se em horas de paragem, e a resposta habitual dos fornecedores e "doze semanas". Temos em stock redutores [helicoidais, conicos e planetarios] e substituicoes compativeis com [SEW, Flender, David Brown] - [X] dias ate Angola, com recondicionamento por troca. Se me enviar as unidades da vossa lista de pecas criticas, respondo com preco e prazo, para terem uma segunda fonte registada antes de precisarem. [SEU NOME] [SUA EMPRESA] | [TELEFONE] | H11: Basta uma foto da chapa de caracteristicas - devolvo orcamento e prazo no mesmo dia.
A12: M7 | B12: Agro, food & cement plants | C12: English | D12: =COUNTIF(Leads!$I$2:$I$201,A12) | E12: National Milling, Olam, Cargill, Dangote, Chilanga Cement, Trade Kings, Varun Beverages, Botswana Meat Commission, Lactalis, PepsiCo, Coca-Cola, Irvine's | F12: Gearbox spares before your next shutdown | G12: Hi {First}, Plants like {Company} buy drive spares before the season, not during it - a gearbox failing mid-run costs far more than the part. We supply [helical, bevel-helical, planetary and shaft-mounted] gearboxes for mills, mixers, conveyors and elevators - [X] days into {Country}. If you tell me roughly when your next shutdown falls, I'll quote the units worth having on the shelf before it. [YOUR NAME] [YOUR COMPANY] | [PHONE] | H12: When is the next shutdown window? I'll work backwards from it so the parts land in time.
A13: M8 | B13: Agro-industria, bebidas e cimento | C13: Portuguese | D13: =COUNTIF(Leads!$I$2:$I$201,A13) | E13: Carrinho Group, Castel Africa, Refriango, Webcor Group, Unique Beverages, BEFCO, FOZKUDIA, Nampak, MAXAM | F13: Redutores antes da proxima paragem programada | G13: Ola {First}, Fabricas como a {Company} compram pecas de transmissao antes da campanha, nao durante - porque um redutor a falhar em producao custa muito mais do que a peca. Fornecemos redutores [helicoidais, conicos, planetarios e de eixo oco] para moinhos, misturadoras, transportadores e elevadores - [X] dias ate Angola. Se me indicar a data da proxima paragem, orcamento as unidades que deveriam estar em stock antes disso. [SEU NOME] [SUA EMPRESA] | [TELEFONE] | H13: Quando esta prevista a proxima paragem? Trabalho a partir dessa data para as pecas chegarem a tempo.
A14: M9 | B14: Energy, utilities & logistics | C14: English | D14: =COUNTIF(Leads!$I$2:$I$201,A14) | E14: ZESCO, Copperbelt Energy, Botswana Power, Vivo Energy, Puma Energy, Juba Transport, SABOT, Simba Group, Africa Global Logistics, Lake Oil | F14: Drive and gearbox spares for {Company} | G14: Hi {First}, Fleet, materials-handling and plant drives fail the same way everywhere: the machine is available, the gearbox is not. We supply [industrial, shaft-mounted and mobile] gearboxes plus travel and swing drives - [X] days into {Country}, with rebuild-on-exchange. Send me the drives that give you the most trouble and I'll come back with price and lead time. If we're not better than your current source, nothing lost. [YOUR NAME] [YOUR COMPANY] | [PHONE] | H14: Do you keep a critical spares list? I'll price the gearbox lines on it so you have a benchmark.
A15: M10 | B15: Petroleo, gas e maritimo | C15: Portuguese | D15: =COUNTIF(Leads!$I$2:$I$201,A15) | E15: Azule Energy, TotalEnergies, ExxonMobil, Chevron, PETROBEL, Siemens Energy, Petromar, SONILS, CONSUL-MARINE, Pumangol, Core Laboratories, DOF | F15: Redutores e acionamentos para a {Company} | G15: Ola {First}, Em operacoes offshore e portuarias o equipamento costuma estar disponivel - o redutor e que nao esta. Fornecemos redutores [industriais, de eixo oco e maritimos], guinchos e acionamentos, com [X] dias ate Angola e recondicionamento por troca. Envie-me os acionamentos que mais problemas dao e respondo com preco e prazo. Se nao formos melhores que a vossa fonte actual, nao perdeu nada. Posso enviar o nosso perfil de empresa para registo de fornecedor? [SEU NOME] [SUA EMPRESA] | [TELEFONE] | H15: Precisa da documentacao de qualificacao de fornecedor? Envio hoje.
A16: M11 | B16: Compras e aprovisionamento | C16: Portuguese | D16: =COUNTIF(Leads!$I$2:$I$201,A16) | E16: Compradores e responsaveis de aprovisionamento na Azule Energy, TotalEnergies, ExxonMobil, Endiama, Petromar, TechnipFMC, Refriango, Webcor Group, Castel Africa | F16: Segunda fonte para redutores e pecas de transmissao | G16: Ola {First}, Grande parte da despesa em redutores em Angola concentra-se num unico fornecedor com prazos longos. Funciona ate a unidade estar em rutura. Fornecemos redutores [helicoidais, conicos e planetarios] e substituicoes compativeis com [SEW, Flender, David Brown] - [X] dias ate Angola, com recondicionamento por troca. Nao e preciso mudar de fornecedor: basta consultarem-nos como segunda fonte. Envie-me as vossas linhas de redutores e devolvo precos e prazos. O que precisam da nossa parte para o registo de fornecedor? [SEU NOME] [SUA EMPRESA] | [TELEFONE] | H16: Envio o perfil da empresa e a documentacao de conformidade para o registo de fornecedor?
A17: Total | D17: =SUM(D6:D16)

Sheet Leads
A1: First name | B1: Last name | C1: Title | D1: Company | E1: Country | F1: City | G1: Segment | H1: Tier | I1: Mail | J1: Email | K1: Language | L1: LinkedIn | M1: Company domain | N1: Company phone | O1: Employees | P1: Industry | Q1: Suggested angle | R1: Check | S1: Status | T1: Date sent | U1: Replied | V1: Notes
A2: Ivo | B2: Araujo | C2: General Manager Angola | D2: CENTROCAR - Centro de Equipamentos Mecânicos S.A. | E2: Angola | F2: Luanda | G2: Distributor | H2: A | I2: M3 | J2: ivo.araujo@centrocar.com | K2: Portuguese | L2: http://www.linkedin.com/in/ivo-araujo-9470b849 | M2: centrocar.com | N2: +351 22 002 9150 | O2: 150 | P2: machinery | Q2: Stocking terms and margin - lead with the commercial offer to the MD/GM, not the spec sheet | R2: HQ abroad (Portugal) - verify local buying authority | S2: Not contacted
A3: Luca | B3: Sassella | C3: Managing Director | D3: E.A.T.S Metering Systems | E3: Angola | G3: Distributor | H3: A | I3: M3 | J3: luca.sassella@eats.ao | K3: Portuguese | L3: http://www.linkedin.com/in/luca-sassella-6b69765 | M3: eats.ao | N3: +244 931 878 469 | O3: 9 | P3: oil & energy | Q3: Stocking terms and margin - lead with the commercial offer to the MD/GM, not the spec sheet | S3: Not contacted
A4: Eduardo | B4: Fernandez | C4: Managing Director | D4: ENCOM Lda. | E4: Angola | F4: Luanda | G4: Distributor | H4: A | I4: M3 | J4: eduardo.fernandez@encom.it.ao | K4: Portuguese | L4: http://www.linkedin.com/in/edufernandez | M4: encom.it.ao | N4: +1 713-429-5084 | O4: 24 | P4: oil & energy | Q4: Stocking terms and margin - lead with the commercial offer to the MD/GM, not the spec sheet | S4: Not contacted
A5: Jose | B5: Santos | C5: General Manager | D5: ENERLINE, SA | E5: Angola | F5: Luanda | G5: Distributor | H5: A | I5: M3 | J5: josesantos@enerline.ao | K5: Portuguese | L5: http://www.linkedin.com/in/jose-santos-9193b9253 | M5: enerline.ao | O5: 250 | P5: oil & energy | Q5: Stocking terms and margin - lead with the commercial offer to the MD/GM, not the spec sheet | S5: Not contacted
A6: Jose | B6: Garrido | C6: Director Geral Adjunto de Sucursal Angola | D6: Elecnor Group | E6: Angola | F6: Luanda | G6: Distributor | H6: A | I6: M3 | J6: jlgarrido@elecnor.com | K6: Portuguese | L6: http://www.linkedin.com/in/jose-luis-garrido-34110623 | M6: grupoelecnor.com | O6: 29000 | P6: construction | Q6: Stocking terms and margin - lead with the commercial offer to the MD/GM, not the spec sheet | R6: HQ abroad (Spain) - verify local buying authority | S6: Not contacted
A7: Januario | B7: Cuela | C7: Branch Manager Angola | D7: GEA Group | E7: Angola | G7: Distributor | H7: A | I7: M3 | J7: januario.cuela@gea.com | K7: Portuguese | L7: http://www.linkedin.com/in/januario-cuela-985a1538 | M7: gea.com | N7: +49 211 91360 | O7: 20000 | P7: machinery | Q7: Stocking terms and margin - lead with the commercial offer to the MD/GM, not the spec sheet | R7: HQ abroad (Germany) - verify local buying authority | S7: Not contacted
A8: Rayan | B8: Farhat | C8: Managing Director and Founder | D8: Industryhub | E8: Angola | F8: Luanda | G8: Distributor | H8: A | I8: M3 | J8: rayan.farhat@industryhubangola.com | K8: Portuguese | L8: http://www.linkedin.com/in/rayan-farhat | M8: industryhubangola.com | O8: 11 | P8: automotive | Q8: Stocking terms and margin - lead with the commercial offer to the MD/GM, not the spec sheet | S8: Not contacted
A9: Nasim | B9: Kayali | C9: General Manager | D9: Mega Mecanix | E9: Angola | G9: Distributor | H9: A | I9: M3 | J9: n.kayali@mecanixsal.com | K9: Portuguese | L9: http://www.linkedin.com/in/nasim-kayali-0bbb2937 | M9: mecanixsal.com | N9: +961 5 950 866 | O9: 19 | P9: machinery | Q9: Stocking terms and margin - lead with the commercial offer to the MD/GM, not the spec sheet | S9: Not contacted
A10: Paulo | B10: Rodrigues | C10: General Manager | D10: Movicortes Angola | E10: Angola | F10: Luanda | G10: Distributor | H10: A | I10: M3 | J10: paulo.rodrigues@movicortes.pt | K10: Portuguese | L10: http://www.linkedin.com/in/paulo-rodrigues-a35823164 | M10: movicortesangola.com | O10: 7 | P10: machinery | Q10: Stocking terms and margin - lead with the commercial offer to the MD/GM, not the spec sheet | S10: Not contacted
A11: Peter | B11: Mashangu | C11: Managing Director | D11: Nampak | E11: Angola | F11: Luanda | G11: Distributor | H11: A | I11: M3 | J11: peter.mashangu@nampak.com | K11: Portuguese | L11: http://www.linkedin.com/in/peter-mashangu-394611159 | M11: nampak.com | N11: +27 11 719 6300 | O11: 2500 | P11: packaging & containers | Q11: Stocking terms and margin - lead with the commercial offer to the MD/GM, not the spec sheet | R11: HQ abroad (South Africa) - verify local buying authority | S11: Not contacted
A12: Kitana | B12: Barbosa | C12: After Sales Director | D12: Nors Group | E12: Angola | F12: Luanda | G12: Distributor | H12: A | I12: M3 | J12: kbarbosa@nors.com | K12: Portuguese | L12: http://www.linkedin.com/in/kitana-barbosa-b3b58486 | M12: nors.com | N12: +351 22 615 0320 | O12: 3200 | P12: automotive | Q12: Stocking terms and margin - lead with the commercial offer to the MD/GM, not the spec sheet | R12: HQ abroad (Portugal) - verify local buying authority | S12: Not contacted
A13: Jean | B13: Rodrigues | C13: Executive Managing Director | D13: OG3S Mecanica Lda | E13: Angola | G13: Distributor | H13: A | I13: M3 | J13: jean-philippe.rodrigues@og3s-mecanica.com | K13: Portuguese | L13: http://www.linkedin.com/in/jean-philippe-rodrigues-a727b82b | M13: og3s-mecanica.com | O13: 35 | P13: oil & energy | Q13: Stocking terms and margin - lead with the commercial offer to the MD/GM, not the spec sheet | S13: Not contacted
A14: Luis | B14: Almeida | C14: Managing Director Angola & Mozambique | D14: SPIE Global Services Energy | E14: Angola | F14: Luanda | G14: Distributor | H14: A | I14: M3 | J14: l.almeida@spie.com | K14: Portuguese | L14: http://www.linkedin.com/in/luis-ferreira-de-almeida-34495338 | M14: spie.com | N14: +33 1 34 41 81 81 | O14: 5000 | P14: oil & energy | Q14: Stocking terms and margin - lead with the commercial offer to the MD/GM, not the spec sheet | R14: HQ abroad (France) - verify local buying authority | S14: Not contacted
A15: Nicolas | B15: Monville | C15: Managing Director | D15: TFE GROUP INC | E15: Angola | G15: Distributor | H15: A | I15: M3 | J15: nicolas.monville@grouptfe.com | K15: Portuguese | L15: http://www.linkedin.com/in/nicolas-monville-411a6358 | M15: grouptfe.com | N15: +33 4 66 70 64 10 | O15: 45 | P15: oil & energy | Q15: Stocking terms and margin - lead with the commercial offer to the MD/GM, not the spec sheet | R15: HQ abroad (France) - verify local buying authority | S15: Not contacted
A16: Mathieu | B16: Wallach | C16: Sales Director and General Manager, Southern Africa | D16: Welltec | E16: Angola | G16: Distributor | H16: A | I16: M3 | J16: mwallach@welltec.com | K16: Portuguese | L16: http://www.linkedin.com/in/mathieu-wallach-a9203a59 | M16: welltec.com | N16: +45 48 14 35 14 | O16: 740 | P16: oil & energy | Q16: Stocking terms and margin - lead with the commercial offer to the MD/GM, not the spec sheet | R16: HQ abroad (Denmark) - verify local buying authority | S16: Not contacted
A17: Favor | B17: Marebole | C17: Managing Director | D17: Applied Metrology Services (Pty) Ltd. | E17: Botswana | G17: Distributor | H17: A | I17: M2 | J17: favor@appliedmetrology.co.za | K17: English | L17: http://www.linkedin.com/in/favor-marebole-a060559 | M17: appliedmetrology.co.za | N17: +27 11 568 0386 | O17: 12 | P17: machinery | Q17: Stocking terms and margin - lead with the commercial offer to the MD/GM, not the spec sheet | R17: HQ abroad (South Africa) - verify local buying authority | S17: Not contacted
A18: Bofedile | B18: Moeti | C18: Managing Director | D18: Bofedile Tech Services (Pty) Ltd | E18: Botswana | F18: Gaborone | G18: Distributor | H18: A | I18: M2 | J18: bmoeti@bts-bw.com | K18: English | L18: http://www.linkedin.com/in/bofedile-moeti-6b1b0447 | M18: bts-bw.com | O18: 6 | P18: industrial automation | Q18: Stocking terms and margin - lead with the commercial offer to the MD/GM, not the spec sheet | S18: Not contacted
A19: Wessel | B19: Wessels | C19: Managing Director | D19: Coastal Hire | E19: Botswana | G19: Distributor | H19: A | I19: M1 | J19: wessel@coastalhire.co.za | K19: English | L19: http://www.linkedin.com/in/wessel-wessels-086569146 | M19: coastalhire.co.za | N19: +27 10 158 0525 | O19: 260 | P19: construction / equipment hire | Q19: Stocking terms and margin - lead with the commercial offer to the MD/GM, not the spec sheet | R19: HQ abroad (South Africa) - verify local buying authority | S19: Not contacted
A20: Tichaona | B20: Ndhlovu | C20: Managing Director | D20: Delswiz Manufacturing (Pty) Limited | E20: Botswana | F20: Gaborone | G20: Distributor | H20: A | I20: M2 | J20: tndhlovu@delswizgroup.com | K20: English | L20: http://www.linkedin.com/in/tichaona-ndhlovu-93212b141 | M20: delswizgroup.com | N20: +971 55 157 9261 | O20: 26 | P20: mining & metals | Q20: Stocking terms and margin - lead with the commercial offer to the MD/GM, not the spec sheet | S20: Not contacted
A21: Clayton | B21: Davis | C21: General Manager | D21: HANSA-FLEX AG | E21: Botswana | G21: Distributor | H21: A | I21: M2 | J21: clayton.davis@hansa-flex.com | K21: English | L21: http://www.linkedin.com/in/clayton-davis-a18a377b | M21: hansa-flex.de | N21: +49 42 1489070 | O21: 5200 | P21: machinery / hydraulics | Q21: Stocking terms and margin - lead with the commercial offer to the MD/GM, not the spec sheet | R21: HQ abroad (Germany) - verify local buying authority | S21: Not contacted
A22: Zayd | B22: Bhoyroo | C22: Assistant General Manager | D22: Impex Group | E22: Botswana | G22: Distributor | H22: A | I22: M1 | J22: zayd@impex.co.bw | K22: English | L22: http://www.linkedin.com/in/zayd-bhoyroo-41419b161 | M22: impex.co.bw | O22: 26 | P22: automotive / wholesale | Q22: Stocking terms and margin - lead with the commercial offer to the MD/GM, not the spec sheet | S22: Not contacted
A23: Sonny | B23: Morekisi | C23: Branch Manager | D23: Komatsu Africa Holdings (Pty) Ltd | E23: Botswana | G23: Distributor | H23: A | I23: M1 | J23: sonnym@komatsu.co.za | K23: English | L23: http://www.linkedin.com/in/sonny-morekisi-9b921043 | M23: komatsu.co.za | O23: 360 | P23: machinery | Q23: Stocking terms and margin - lead with the commercial offer to the MD/GM, not the spec sheet | R23: HQ abroad (South Africa) - verify local buying authority | S23: Not contacted
A24: Donovan | B24: Lendrum | C24: Sales Director | D24: Rotating Solutions Botswana | E24: Botswana | F24: Gaborone | G24: Distributor | H24: A | I24: M2 | J24: donovan@rotatingsolutions.co.bw | K24: English | L24: http://www.linkedin.com/in/donovan-lendrum-906a6352 | M24: rotatingsolutions.co.bw | O24: 2 | P24: industrial supply / bearings and lubricants | Q24: Stocking terms and margin - lead with the commercial offer to the MD/GM, not the spec sheet | S24: Not contacted
A25: Tshegofatso | B25: Mosweu | C25: Assistant Manager Procurement | D25: SPTC | E25: Botswana | G25: Distributor | H25: A | I25: M2 | J25: tshegofatso@sptc.com.sa | K25: English | L25: http://www.linkedin.com/in/tshegofatso-mosweu-783017a1 | M25: sptc.com.sa | N25: +966 13 814 4624 | O25: 320 | P25: electrical/electronic manufacturing | Q25: Stocking terms and margin - lead with the commercial offer to the MD/GM, not the spec sheet | R25: HQ abroad (Saudi Arabia) - verify local buying authority | S25: Not contacted
A26: Justice | B26: Moilwa | C26: Managing Director | D26: ZISMO Engineering (Pty) Ltd. | E26: Botswana | F26: Gaborone | G26: Distributor | H26: A | I26: M2 | J26: jmoilwa@zismoengineering.com | K26: English | L26: http://www.linkedin.com/in/justice-moilwa-859595ba | M26: zismoengineeing.com | N26: +267 393 2711 | O26: 58 | P26: electrical/electronic manufacturing | Q26: Stocking terms and margin - lead with the commercial offer to the MD/GM, not the spec sheet | S26: Not contacted
A27: Michael | B27: Bentley | C27: Managing Director | D27: ACTION AUTO ZAMBIA | E27: Zambia | G27: Distributor | H27: A | I27: M1 | J27: m.bentley@actionautozambia.com | K27: English | L27: http://www.linkedin.com/in/michael-bentley-69240073 | M27: actionautozambia.com | O27: 54 | P27: automotive | Q27: Stocking terms and margin - lead with the commercial offer to the MD/GM, not the spec sheet | S27: Not contacted
A28: Sajad | B28: Ahmed | C28: MD | D28: Access Energy Solutions Pty Ltd | E28: Zambia | G28: Distributor | H28: A | I28: M2 | J28: sajad@accessenergys.com | K28: English | L28: http://www.linkedin.com/in/sajad-ahmed-2ba5b5112 | M28: accessenergys.com | O28: 4 | P28: environmental services | Q28: Stocking terms and margin - lead with the commercial offer to the MD/GM, not the spec sheet | S28: Not contacted
A29: Dirk | B29: Wet | C29: Project Operation Manager | D29: BIA GROUP | E29: Zambia | F29: Lusaka | G29: Distributor | H29: A | I29: M1 | J29: dirk.dewet@biagroup.com | K29: English | L29: http://www.linkedin.com/in/dirk-de-wet-8969b189 | M29: biagroup.com | N29: +32 2 689 28 11 | O29: 1300 | P29: machinery | Q29: Stocking terms and margin - lead with the commercial offer to the MD/GM, not the spec sheet | R29: HQ abroad (Mauritius) - verify local buying authority | S29: Not contacted
A30: Cobus | B30: Potgieter | C30: Branch Manager | D30: BL&D Plant Hire & Sales | E30: Zambia | G30: Distributor | H30: A | I30: M1 | J30: cobus@bldequipment.com | K30: English | L30: http://www.linkedin.com/in/cobus-potgieter-68204494 | M30: bldequipment.com | O30: 76 | P30: machinery | Q30: Stocking terms and margin - lead with the commercial offer to the MD/GM, not the spec sheet | S30: Not contacted
A31: Samson | B31: Chingozho | C31: Managing Director | D31: Bell Equipment Mining & Construction | E31: Zambia | G31: Distributor | H31: A | I31: M1 | J31: samson.chingozho@bellequipment.com | K31: English | L31: http://www.linkedin.com/in/samson-chingozho-b584a212 | M31: bellequipment.com | N31: +27 35 907 9111 | O31: 3500 | P31: machinery | Q31: Stocking terms and margin - lead with the commercial offer to the MD/GM, not the spec sheet | R31: HQ abroad (South Africa) - verify local buying authority | S31: Not contacted
A32: Bevin | B32: Samwata | C32: Branch Manager | D32: Blumaq, S.A. | E32: Zambia | F32: Kitwe | G32: Distributor | H32: A | I32: M1 | J32: bevin.samwata@blumaq.com | K32: English | L32: http://www.linkedin.com/in/bevin-samwata-76765a64 | M32: blumaq.com | N32: +34 964 69 70 30 | O32: 250 | P32: machinery | Q32: Stocking terms and margin - lead with the commercial offer to the MD/GM, not the spec sheet | R32: HQ abroad (Spain) - verify local buying authority | S32: Not contacted
A33: Henry | B33: Kapesa | C33: Managing Director | D33: Bordertec Limited | E33: Zambia | G33: Distributor | H33: A | I33: M2 | J33: henry@bordertecltd.com | K33: English | L33: http://www.linkedin.com/in/henry-kapesa-044b16aa | M33: bordertec.co.zm | O33: 5 | P33: management consulting | Q33: Stocking terms and margin - lead with the commercial offer to the MD/GM, not the spec sheet | S33: Not contacted
A34: Jinu | B34: Raj | C34: General Manager | D34: DGC AFRICA | E34: Zambia | G34: Distributor | H34: A | I34: M2 | J34: jinu@dgc-africa.com | K34: English | L34: http://www.linkedin.com/in/jinu-raj-b51a2b15a | M34: dgc-africa.com | N34: +27 16 421 3720 | O34: 200 | P34: mining & metals | Q34: Stocking terms and margin - lead with the commercial offer to the MD/GM, not the spec sheet | R34: HQ abroad (South Africa) - verify local buying authority | S34: Not contacted
A35: Gregory | B35: Gavazzi | C35: Managing Director | D35: Doppio Mining Equipment | E35: Zambia | G35: Distributor | H35: A | I35: M1 | J35: greg@doppioequipment.com | K35: English | L35: http://www.linkedin.com/in/gregory-gavazzi-97ba9713a | M35: doppioequipment.com | O35: 4 | P35: mining & metals | Q35: Stocking terms and margin - lead with the commercial offer to the MD/GM, not the spec sheet | S35: Not contacted
A36: Chongo | B36: Mumba | C36: Technical Sales Manager | D36: Hebei Aojin Machinery Co.,Ltd. | E36: Zambia | G36: Distributor | H36: A | I36: M1 | J36: chongom@aoj-pump.com | K36: English | L36: http://www.linkedin.com/in/chongo-mumba-13295520 | M36: aoj-pump.com | N36: +86 311 8880 2472 | O36: 150 | P36: machinery | Q36: Stocking terms and margin - lead with the commercial offer to the MD/GM, not the spec sheet | R36: HQ abroad (China) - verify local buying authority | S36: Not contacted
A37: Arne | B37: Thorkildsen | C37: Branch Operations Manager | D37: Hitachi Construction Machinery | E37: Zambia | G37: Distributor | H37: A | I37: M1 | J37: arne.thorkildsen@hcmaf.com | K37: English | L37: http://www.linkedin.com/in/arne-thorkildsen-336b2b82 | M37: hitachicm.com | N37: +81 358-26-8100 | O37: 26000 | P37: machinery | Q37: Stocking terms and margin - lead with the commercial offer to the MD/GM, not the spec sheet | R37: HQ abroad (Japan) - verify local buying authority | S37: Not contacted
A38: Henri | B38: Wassink | C38: Managing Director - Administration | D38: Liebherr Group | E38: Zambia | G38: Distributor | H38: A | I38: M1 | J38: hendrik.wassink@liebherr.com | K38: English | L38: http://www.linkedin.com/in/henri-wassink-60322140 | M38: liebherr.com | N38: +49 735 1410 | O38: 54000 | P38: machinery | Q38: Stocking terms and margin - lead with the commercial offer to the MD/GM, not the spec sheet | R38: HQ abroad (Germany) - verify local buying authority | S38: Not contacted
A39: Yoginder | B39: Singh | C39: Workshop Manager | D39: R A Consulting Services (RACS) | E39: Zambia | G39: Distributor | H39: A | I39: M2 | J39: yoginder@racsafrica.com | K39: English | L39: http://www.linkedin.com/in/yoginder-singh-944003180 | M39: racsafrica.com | N39: +267 393 9773 | O39: 87 | P39: information technology & services | Q39: Stocking terms and margin - lead with the commercial offer to the MD/GM, not the spec sheet | S39: Not contacted
A40: Simon | B40: Kazunda | C40: Managing Director | D40: SAFE KAHYA Limited | E40: Zambia | G40: Distributor | H40: A | I40: M2 | J40: simon.kazunda@safekahya.com | K40: English | L40: http://www.linkedin.com/in/simon-kazunda-46655b21 | M40: safekahya.com | O40: 1 | P40: electrical/electronic manufacturing | Q40: Stocking terms and margin - lead with the commercial offer to the MD/GM, not the spec sheet | S40: Not contacted
...

Sheet Read me
A1: Gearbox Leads - Batch 1
A3: What this is
A4: 200 contacts in Botswana, Zambia and Angola who buy or resell industrial gearboxes.
A5: Every one has an Apollo-verified work email. No guessed addresses, no info@ catch-alls.
A6: Sourced from Apollo.io on 28 July 2026, across 134 companies.
A8: The Mails tab
A9: The 200 are grouped into 10 clusters of similar companies. Each cluster has its own short email,
A10: because a copper mine, an equipment dealer and a flour mill do not buy for the same reason.
A11: The Mail column on the Leads tab says which email each contact gets. Filter on it and send one
A12: cluster at a time.
A13: Before you send: replace every [BRACKET] with your own details - company name, product range,
A14: lead time in days, your name and phone. I do not know those, so I left them blank on purpose
... A51: Batch 4 - Namibia, DRC Copperbelt, Mozambique, Zimbabwe on the same industrial logic
